Workbook

Sheet linear
A1: N | B1: X | C1: Y | D1: XY | E1: XZ | F1: YZ | G1: Z | H1: Предсказанные значения | I1: Остатки | J1: Для построения линейной двухфакторной регрессии z = b0 + b1x + b2y решим систему уравнений
A2: 1 | B2: 25 | C2: 233 | D2: =B2*C2 -> 5825 | E2: =B2*G2 -> -175 | F2: =C2*G2 -> -1631 | G2: -7 | H2: =$K$10+$K$11*Таблица1[[#This Row],[X]]+$K$12*Таблица1[[#This Row],[Y]] -> -5.893 | I2: =ABS(Таблица1[[#This Row],[Предсказанные значения]]-Таблица1[[#This Row],[Z]]) -> 1.107
A3: 2 | B3: 47 | C3: 432 | D3: =B3*C3 -> 20304 | E3: =B3*G3 -> -282 | F3: =C3*G3 -> -2592 | G3: -6 | H3: =$K$10+$K$11*Таблица1[[#This Row],[X]]+$K$12*Таблица1[[#This Row],[Y]] -> -5.963 | I3: =ABS(Таблица1[[#This Row],[Предсказанные значения]]-Таблица1[[#This Row],[Z]]) -> 0.037
A4: 3 | B4: 42 | C4: 385 | D4: =B4*C4 -> 16170 | E4: =B4*G4 -> -420 | F4: =C4*G4 -> -3850 | G4: -10 | H4: =$K$10+$K$11*Таблица1[[#This Row],[X]]+$K$12*Таблица1[[#This Row],[Y]] -> -5.745 | I4: =ABS(Таблица1[[#This Row],[Предсказанные значения]]-Таблица1[[#This Row],[Z]]) -> 4.255
A5: 4 | B5: 38 | C5: 347 | D5: =B5*C5 -> 13186 | E5: =B5*G5 -> -38 | F5: =C5*G5 -> -347 | G5: -1 | H5: =$K$10+$K$11*Таблица1[[#This Row],[X]]+$K$12*Таблица1[[#This Row],[Y]] -> -5.525 | I5: =ABS(Таблица1[[#This Row],[Предсказанные значения]]-Таблица1[[#This Row],[Z]]) -> 4.525
A6: 5 | B6: 30 | C6: 274 | D6: =B6*C6 -> 8220 | E6: =B6*G6 -> -60 | F6: =C6*G6 -> -548 | G6: -2 | H6: =$K$10+$K$11*Таблица1[[#This Row],[X]]+$K$12*Таблица1[[#This Row],[Y]] -> -5.427 | I6: =ABS(Таблица1[[#This Row],[Предсказанные значения]]-Таблица1[[#This Row],[Z]]) -> 3.427
A7: 6 | B7: 30 | C7: 276 | D7: =B7*C7 -> 8280 | E7: =B7*G7 -> -180 | F7: =C7*G7 -> -1656 | G7: -6 | H7: =$K$10+$K$11*Таблица1[[#This Row],[X]]+$K$12*Таблица1[[#This Row],[Y]] -> -5.655 | I7: =ABS(Таблица1[[#This Row],[Предсказанные значения]]-Таблица1[[#This Row],[Z]]) -> 0.345 | J7: где x1 = x, x2 = y (экзогенные переменные), y=z (эндогенная переменная)
A8: 7 | B8: 32 | C8: 294 | D8: =B8*C8 -> 9408 | E8: =B8*G8 -> -192 | F8: =C8*G8 -> -1764 | G8: -6 | H8: =$K$10+$K$11*Таблица1[[#This Row],[X]]+$K$12*Таблица1[[#This Row],[Y]] -> -5.651 | I8: =ABS(Таблица1[[#This Row],[Предсказанные значения]]-Таблица1[[#This Row],[Z]]) -> 0.349 | J8: Решая систему, получаем следующие коэффициенты
A9: 8 | B9: 38 | C9: 348 | D9: =B9*C9 -> 13224 | E9: =B9*G9 -> -190 | F9: =C9*G9 -> -1740 | G9: -5 | H9: =$K$10+$K$11*Таблица1[[#This Row],[X]]+$K$12*Таблица1[[#This Row],[Y]] -> -5.639 | I9: =ABS(Таблица1[[#This Row],[Предсказанные значения]]-Таблица1[[#This Row],[Z]]) -> 0.639 | J9: Коэффициенты | K9: Значения | L9: Содержательный смысл
A10: 9 | B10: 34 | C10: 315 | D10: =B10*C10 -> 10710 | E10: =B10*G10 -> -340 | F10: =C10*G10 -> -3150 | G10: -10 | H10: =$K$10+$K$11*Таблица1[[#This Row],[X]]+$K$12*Таблица1[[#This Row],[Y]] -> -5.989 | I10: =ABS(Таблица1[[#This Row],[Предсказанные значения]]-Таблица1[[#This Row],[Z]]) -> 4.011 | J10: b0 | K10: -5.031 | L10: Это значение Z, когда все независимые переменные равны нулю. Свободный член - базовый уровень зависимой переменной
A11: 10 | B11: 34 | C11: 307 | D11: =B11*C11 -> 10438 | E11: =B11*G11 -> -136 | F11: =C11*G11 -> -1228 | G11: -4 | H11: =$K$10+$K$11*Таблица1[[#This Row],[X]]+$K$12*Таблица1[[#This Row],[Y]] -> -5.077 | I11: =ABS(Таблица1[[#This Row],[Предсказанные значения]]-Таблица1[[#This Row],[Z]]) -> 1.077 | J11: b1 | K11: 1.028 | L11: Показывает, на сколько изменится Z при изменении X​ на единицу, при условии, что Y​ остаётся неизменным.
A12: 11 | B12: 41 | C12: 377 | D12: =B12*C12 -> 15457 | E12: =B12*G12 -> -369 | F12: =C12*G12 -> -3393 | G12: -9 | H12: =$K$10+$K$11*Таблица1[[#This Row],[X]]+$K$12*Таблица1[[#This Row],[Y]] -> -5.861 | I12: =ABS(Таблица1[[#This Row],[Предсказанные значения]]-Таблица1[[#This Row],[Z]]) -> 3.139 | J12: b2 | K12: -0.114 | L12: Показывает, на сколько изменится Z при изменении Y на единицу, при условии, что X​ остаётся неизменным.
A13: 12 | B13: 37 | C13: 338 | D13: =B13*C13 -> 12506 | E13: =B13*G13 -> -185 | F13: =C13*G13 -> -1690 | G13: -5 | H13: =$K$10+$K$11*Таблица1[[#This Row],[X]]+$K$12*Таблица1[[#This Row],[Y]] -> -5.527 | I13: =ABS(Таблица1[[#This Row],[Предсказанные значения]]-Таблица1[[#This Row],[Z]]) -> 0.527 | J13: По сути коэффициенты показывают частную производную (оно и понятно, ведь можем взять и продифференцировать)
A14: 13 | B14: 39 | C14: 353 | D14: =B14*C14 -> 13767 | E14: =B14*G14 -> -273 | F14: =C14*G14 -> -2471 | G14: -7 | H14: =$K$10+$K$11*Таблица1[[#This Row],[X]]+$K$12*Таблица1[[#This Row],[Y]] -> -5.181 | I14: =ABS(Таблица1[[#This Row],[Предсказанные значения]]-Таблица1[[#This Row],[Z]]) -> 1.819
A15: 14 | B15: 36 | C15: 332 | D15: =B15*C15 -> 11952 | E15: =B15*G15 -> -108 | F15: =C15*G15 -> -996 | G15: -3 | H15: =$K$10+$K$11*Таблица1[[#This Row],[X]]+$K$12*Таблица1[[#This Row],[Y]] -> -5.871 | I15: =ABS(Таблица1[[#This Row],[Предсказанные значения]]-Таблица1[[#This Row],[Z]]) -> 2.871 | J15: Средняя ошибка аппроксимации (mae) | K15: =SUM(Таблица1[Остатки])/COUNT(Таблица1[Остатки]) -> 2.5504667 | L15: Высокая ошибка, учитывая значения Z (выходим за 8-10%)!
A16: 15 | B16: 34 | C16: 307 | D16: =B16*C16 -> 10438 | E16: =B16*G16 -> -340 | F16: =C16*G16 -> -3070 | G16: -10 | H16: =$K$10+$K$11*Таблица1[[#This Row],[X]]+$K$12*Таблица1[[#This Row],[Y]] -> -5.077 | I16: =ABS(Таблица1[[#This Row],[Предсказанные значения]]-Таблица1[[#This Row],[Z]]) -> 4.923 | J16: Частный коэффициент эластичности Ex | K16: =K11*AVERAGE(Таблица1[X])/AVERAGE(Таблица1[Z]) -> -6.6633468 | L16: Его влияние на результативный признак существенно, так как |Ex| >= 1
A17: 16 | B17: 29 | C17: 264 | D17: =B17*C17 -> 7656 | E17: =B17*G17 -> -29 | F17: =C17*G17 -> -264 | G17: -1 | H17: =$K$10+$K$11*Таблица1[[#This Row],[X]]+$K$12*Таблица1[[#This Row],[Y]] -> -5.315 | I17: =ABS(Таблица1[[#This Row],[Предсказанные значения]]-Таблица1[[#This Row],[Z]]) -> 4.315 | J17: Частный коэффициент эластичности Ey | K17: =K12*AVERAGE(Таблица1[X])/AVERAGE(Таблица1[Z]) -> 0.73893145 | L17: Его влияние на результативный признак незначительно, так как |Ey| < 1
A18: 17 | B18: 31 | C18: 285 | D18: =B18*C18 -> 8835 | E18: =B18*G18 -> -93 | F18: =C18*G18 -> -855 | G18: -3 | H18: =$K$10+$K$11*Таблица1[[#This Row],[X]]+$K$12*Таблица1[[#This Row],[Y]] -> -5.653 | I18: =ABS(Таблица1[[#This Row],[Предсказанные значения]]-Таблица1[[#This Row],[Z]]) -> 2.653
A19: 18 | B19: 41 | C19: 377 | D19: =B19*C19 -> 15457 | E19: =B19*G19 -> -205 | F19: =C19*G19 -> -1885 | G19: -5 | H19: =$K$10+$K$11*Таблица1[[#This Row],[X]]+$K$12*Таблица1[[#This Row],[Y]] -> -5.861 | I19: =ABS(Таблица1[[#This Row],[Предсказанные значения]]-Таблица1[[#This Row],[Z]]) -> 0.861 | J19: Исследуем факторы на мультиколлинеарность, для этого найдём коэффициент корреляции rxy
A20: 19 | B20: 15 | C20: 137 | D20: =B20*C20 -> 2055 | E20: =B20*G20 -> -75 | F20: =C20*G20 -> -685 | G20: -5 | H20: =$K$10+$K$11*Таблица1[[#This Row],[X]]+$K$12*Таблица1[[#This Row],[Y]] -> -5.229 | I20: =ABS(Таблица1[[#This Row],[Предсказанные значения]]-Таблица1[[#This Row],[Z]]) -> 0.229 | J20: cov(x,y) | K20: =COVAR(Таблица1[X], Таблица1[Y])*COUNT(Таблица1[X]) -> 63037.389
A21: 20 | B21: 27 | C21: 245 | D21: =B21*C21 -> 6615 | E21: =B21*G21 -> -27 | F21: =C21*G21 -> -245 | G21: -1 | H21: =$K$10+$K$11*Таблица1[[#This Row],[X]]+$K$12*Таблица1[[#This Row],[Y]] -> -5.205 | I21: =ABS(Таблица1[[#This Row],[Предсказанные значения]]-Таблица1[[#This Row],[Z]]) -> 4.205 | J21: Sx | K21: =SQRT(help_linear!J2) -> 83.63047
A22: 21 | B22: 46 | C22: 421 | D22: =B22*C22 -> 19366 | E22: =B22*G22 -> 46 | F22: =C22*G22 -> 421 | G22: 1 | H22: =$K$10+$K$11*Таблица1[[#This Row],[X]]+$K$12*Таблица1[[#This Row],[Y]] -> -5.737 | I22: =ABS(Таблица1[[#This Row],[Предсказанные значения]]-Таблица1[[#This Row],[Z]]) -> 6.737 | J22: Sy | K22: =SQRT(help_linear!J3) -> 754.13415
A23: 22 | B23: 34 | C23: 313 | D23: =B23*C23 -> 10642 | E23: =B23*G23 -> -340 | F23: =C23*G23 -> -3130 | G23: -10 | H23: =$K$10+$K$11*Таблица1[[#This Row],[X]]+$K$12*Таблица1[[#This Row],[Y]] -> -5.761 | I23: =ABS(Таблица1[[#This Row],[Предсказанные значения]]-Таблица1[[#This Row],[Z]]) -> 4.239 | J23: rxy | K23: =K20/(K21*K22) -> 0.99950522 | L23: Коэффициент, близкий к 1, говорит о близкой зависимости между переменными (что и говорилось во 2 лабораторной)!
A24: 23 | B24: 39 | C24: 359 | D24: =B24*C24 -> 14001 | E24: =B24*G24 -> -117 | F24: =C24*G24 -> -1077 | G24: -3 | H24: =$K$10+$K$11*Таблица1[[#This Row],[X]]+$K$12*Таблица1[[#This Row],[Y]] -> -5.865 | I24: =ABS(Таблица1[[#This Row],[Предсказанные значения]]-Таблица1[[#This Row],[Z]]) -> 2.865
A25: 24 | B25: 49 | C25: 443 | D25: =B25*C25 -> 21707 | E25: =B25*G25 -> -441 | F25: =C25*G25 -> -3987 | G25: -9 | H25: =$K$10+$K$11*Таблица1[[#This Row],[X]]+$K$12*Таблица1[[#This Row],[Y]] -> -5.161 | I25: =ABS(Таблица1[[#This Row],[Предсказанные значения]]-Таблица1[[#This Row],[Z]]) -> 3.839 | J25: Коэффициент детерминации | K25: =1-SUMSQ(Таблица1[Остатки])/SUMSQ(Таблица3[Отклонения Z]) -> 0.0085999369 | L25: Так как значение близко к 0, то модель слабо аппроксимирует данные
A26: 25 | B26: 22 | C26: 201 | D26: =B26*C26 -> 4422 | E26: =B26*G26 -> -132 | F26: =C26*G26 -> -1206 | G26: -6 | H26: =$K$10+$K$11*Таблица1[[#This Row],[X]]+$K$12*Таблица1[[#This Row],[Y]] -> -5.329 | I26: =ABS(Таблица1[[#This Row],[Предсказанные значения]]-Таблица1[[#This Row],[Z]]) -> 0.671 | J26: Коэффициент парной корреляции rxz | K26: =COVAR(Таблица1[X],Таблица1[Z])*COUNT(Таблица1[X])/(K21*SQRT(help_linear!J4)) -> 0.0025542176 | L26: =K26*SQRT(COUNT(Таблица1[X])-2)/SQRT(1-K26^2) -> 0.023960763 | M26: Не значим
A27: 26 | B27: 48 | C27: 440 | D27: =B27*C27 -> 21120 | E27: =B27*G27 -> -96 | F27: =C27*G27 -> -880 | G27: -2 | H27: =$K$10+$K$11*Таблица1[[#This Row],[X]]+$K$12*Таблица1[[#This Row],[Y]] -> -5.847 | I27: =ABS(Таблица1[[#This Row],[Предсказанные значения]]-Таблица1[[#This Row],[Z]]) -> 3.847 | J27: Коэффициент парной корреляции ryz | K27: =COVAR(Таблица1[Y],Таблица1[Z])*COUNT(Таблица1[Y])/(K22*SQRT(help_linear!J4)) -> -0.00036620508 | L27: =K27*SQRT(COUNT(Таблица1[X])-2)/SQRT(1-K27^2) -> -0.0034353084 | M27: Не значим
A28: 27 | B28: 30 | C28: 274 | D28: =B28*C28 -> 8220 | E28: =B28*G28 -> -60 | F28: =C28*G28 -> -548 | G28: -2 | H28: =$K$10+$K$11*Таблица1[[#This Row],[X]]+$K$12*Таблица1[[#This Row],[Y]] -> -5.427 | I28: =ABS(Таблица1[[#This Row],[Предсказанные значения]]-Таблица1[[#This Row],[Z]]) -> 3.427 | J28: Коэффициент парной корреляции rxy | K28: =K23 -> 0.99950522 | L28: =K28*SQRT(COUNT(Таблица1[X])-2)/SQRT(1-K28^2) -> 298.09815 | M28: Значим (так как t-статистическое > t-критическое)
A29: 28 | B29: 29 | C29: 261 | D29: =B29*C29 -> 7569 | E29: =B29*G29 -> -232 | F29: =C29*G29 -> -2088 | G29: -8 | H29: =$K$10+$K$11*Таблица1[[#This Row],[X]]+$K$12*Таблица1[[#This Row],[Y]] -> -4.973 | I29: =ABS(Таблица1[[#This Row],[Предсказанные значения]]-Таблица1[[#This Row],[Z]]) -> 3.027 | J29: Частный коэффициент корреляции r_zx/y | K29: =(K26-K27*K28)/(SQRT((1-K27^2)*(1-K28^2))) -> 0.092843538 | L29: Теснота связи низкая | O29: t-критическое | P29: =_xlfn.T.INV(0.95,COUNT(Таблица1[X])-2) -> 1.662354
A30: 29 | B30: 29 | C30: 270 | D30: =B30*C30 -> 7830 | E30: =B30*G30 -> -261 | F30: =C30*G30 -> -2430 | G30: -9 | H30: =$K$10+$K$11*Таблица1[[#This Row],[X]]+$K$12*Таблица1[[#This Row],[Y]] -> -5.999 | I30: =ABS(Таблица1[[#This Row],[Предсказанные значения]]-Таблица1[[#This Row],[Z]]) -> 3.001 | J30: Частный коэффициент корреляции r_zy/x | K30: =(K27-K28*K26)/(SQRT((1-K28^2)*(1-K26^2))) -> -0.092809416
A31: 30 | B31: 38 | C31: 345 | D31: =B31*C31 -> 13110 | E31: =B31*G31 -> -76 | F31: =C31*G31 -> -690 | G31: -2 | H31: =$K$10+$K$11*Таблица1[[#This Row],[X]]+$K$12*Таблица1[[#This Row],[Y]] -> -5.297 | I31: =ABS(Таблица1[[#This Row],[Предсказанные значения]]-Таблица1[[#This Row],[Z]]) -> 3.297
A32: 31 | B32: 37 | C32: 334 | D32: =B32*C32 -> 12358 | E32: =B32*G32 -> -296 | F32: =C32*G32 -> -2672 | G32: -8 | H32: =$K$10+$K$11*Таблица1[[#This Row],[X]]+$K$12*Таблица1[[#This Row],[Y]] -> -5.071 | I32: =ABS(Таблица1[[#This Row],[Предсказанные значения]]-Таблица1[[#This Row],[Z]]) -> 2.929 | J32: Проверим качество модели:
A33: 32 | B33: 55 | C33: 498 | D33: =B33*C33 -> 27390 | E33: =B33*G33 -> -495 | F33: =C33*G33 -> -4482 | G33: -9 | H33: =$K$10+$K$11*Таблица1[[#This Row],[X]]+$K$12*Таблица1[[#This Row],[Y]] -> -5.263 | I33: =ABS(Таблица1[[#This Row],[Предсказанные значения]]-Таблица1[[#This Row],[Z]]) -> 3.737 | J33: F-статистика | K33: =K25*(COUNT(Таблица1[X])-2)/((1-K25)*2) -> 0.38167964
A34: 33 | B34: 38 | C34: 342 | D34: =B34*C34 -> 12996 | E34: =B34*G34 -> -266 | F34: =C34*G34 -> -2394 | G34: -7 | H34: =$K$10+$K$11*Таблица1[[#This Row],[X]]+$K$12*Таблица1[[#This Row],[Y]] -> -4.955 | I34: =ABS(Таблица1[[#This Row],[Предсказанные значения]]-Таблица1[[#This Row],[Z]]) -> 2.045 | J34: F-критическое | K34: =FINV(0.05, 2, COUNT(Таблица1[X])-2) -> 3.1000686
A35: 34 | B35: 27 | C35: 250 | D35: =B35*C35 -> 6750 | E35: =B35*G35 -> -54 | F35: =C35*G35 -> -500 | G35: -2 | H35: =$K$10+$K$11*Таблица1[[#This Row],[X]]+$K$12*Таблица1[[#This Row],[Y]] -> -5.775 | I35: =ABS(Таблица1[[#This Row],[Предсказанные значения]]-Таблица1[[#This Row],[Z]]) -> 3.775 | J35: Модель не линейная на уровне значимости alpha = 0.05
A36: 35 | B36: 44 | C36: 403 | D36: =B36*C36 -> 17732 | E36: =B36*G36 -> -220 | F36: =C36*G36 -> -2015 | G36: -5 | H36: =$K$10+$K$11*Таблица1[[#This Row],[X]]+$K$12*Таблица1[[#This Row],[Y]] -> -5.741 | I36: =ABS(Таблица1[[#This Row],[Предсказанные значения]]-Таблица1[[#This Row],[Z]]) -> 0.741
A37: 36 | B37: 48 | C37: 434 | D37: =B37*C37 -> 20832 | E37: =B37*G37 -> -144 | F37: =C37*G37 -> -1302 | G37: -3 | H37: =$K$10+$K$11*Таблица1[[#This Row],[X]]+$K$12*Таблица1[[#This Row],[Y]] -> -5.163 | I37: =ABS(Таблица1[[#This Row],[Предсказанные значения]]-Таблица1[[#This Row],[Z]]) -> 2.163 | J37: Проверим качество коэффициентов: | M37: Вычисленные стандартные ошибки коэффициентов
A38: 37 | B38: 35 | C38: 320 | D38: =B38*C38 -> 11200 | E38: =B38*G38 -> -210 | F38: =C38*G38 -> -1920 | G38: -6 | H38: =$K$10+$K$11*Таблица1[[#This Row],[X]]+$K$12*Таблица1[[#This Row],[Y]] -> -5.531 | I38: =ABS(Таблица1[[#This Row],[Предсказанные значения]]-Таблица1[[#This Row],[Z]]) -> 0.469 | J38: t-b0 | K38: =ABS(K10)/N38 -> 3.3787777 | L38: Отвергаем | M38: b0 | N38: 1.489
A39: 38 | B39: 35 | C39: 318 | D39: =B39*C39 -> 11130 | E39: =B39*G39 -> -350 | F39: =C39*G39 -> -3180 | G39: -10 | H39: =$K$10+$K$11*Таблица1[[#This Row],[X]]+$K$12*Таблица1[[#This Row],[Y]] -> -5.303 | I39: =ABS(Таблица1[[#This Row],[Предсказанные значения]]-Таблица1[[#This Row],[Z]]) -> 4.697 | J39: t-b1 | K39: =ABS(K11)/N39 -> 0.86971235 | L39: Принимаем | M39: b1 | N39: 1.182
A40: 39 | B40: 28 | C40: 256 | D40: =B40*C40 -> 7168 | E40: =B40*G40 -> -112 | F40: =C40*G40 -> -1024 | G40: -4 | H40: =$K$10+$K$11*Таблица1[[#This Row],[X]]+$K$12*Таблица1[[#This Row],[Y]] -> -5.431 | I40: =ABS(Таблица1[[#This Row],[Предсказанные значения]]-Таблица1[[#This Row],[Z]]) -> 1.431 | J40: t-b2 | K40: =ABS(K12)/N40 -> 0.87022901 | L40: Принимаем | M40: b2 | N40: 0.131
...

Sheet help_linear
A1: X | B1: Y | C1: Z | D1: ln(Z') | E1: Отклонения X | F1: Отклонения Y | G1: Отклонения Z | H1: Отклонения ln(Z')
A2: 25 | B2: 233 | C2: -7 | D2: =LN(Таблица3[[#This Row],[Z]]+exponential!$R$3) -> 1.6094379 | E2: =A2-AVERAGE($A$2:$A$91) -> -10.722222 | F2: =B2-AVERAGE($B$2:$B$91) -> -93.455556 | G2: =Таблица3[[#This Row],[Z]]-AVERAGE(Таблица3[Z]) -> -1.4888889 | H2: =Таблица3[[#This Row],[ln(Z'')]]-AVERAGE(Таблица3[ln(Z'')]) -> -0.12197016 | I2: Sx^2 | J2: =SUMSQ($E$2:$E$91) -> 6994.0556
A3: 47 | B3: 432 | C3: -6 | D3: =LN(Таблица3[[#This Row],[Z]]+exponential!$R$3) -> 1.7917595 | E3: =A3-AVERAGE($A$2:$A$91) -> 11.277778 | F3: =B3-AVERAGE($B$2:$B$91) -> 105.54444 | G3: =Таблица3[[#This Row],[Z]]-AVERAGE(Таблица3[Z]) -> -0.48888889 | H3: =Таблица3[[#This Row],[ln(Z'')]]-AVERAGE(Таблица3[ln(Z'')]) -> 0.060351401 | I3: Sy^2 | J3: =SUMSQ($F$2:$F$91) -> 568718.32
A4: 42 | B4: 385 | C4: -10 | D4: =LN(Таблица3[[#This Row],[Z]]+exponential!$R$3) -> 0.69314718 | E4: =A4-AVERAGE($A$2:$A$91) -> 6.2777778 | F4: =B4-AVERAGE($B$2:$B$91) -> 58.544444 | G4: =Таблица3[[#This Row],[Z]]-AVERAGE(Таблица3[Z]) -> -4.4888889 | H4: =Таблица3[[#This Row],[ln(Z'')]]-AVERAGE(Таблица3[ln(Z'')]) -> -1.0382609 | I4: Sz^2 | J4: =SUMSQ($G$2:$G$91) -> 848.48889
A5: 38 | B5: 347 | C5: -1 | D5: =LN(Таблица3[[#This Row],[Z]]+exponential!$R$3) -> 2.3978953 | E5: =A5-AVERAGE($A$2:$A$91) -> 2.2777778 | F5: =B5-AVERAGE($B$2:$B$91) -> 20.544444 | G5: =Таблица3[[#This Row],[Z]]-AVERAGE(Таблица3[Z]) -> 4.5111111 | H5: =Таблица3[[#This Row],[ln(Z'')]]-AVERAGE(Таблица3[ln(Z'')]) -> 0.6664872 | I5: Sz'^2 | J5: =SUMSQ($D$2:$D$91) -> 298.35915
A6: 30 | B6: 274 | C6: -2 | D6: =LN(Таблица3[[#This Row],[Z]]+exponential!$R$3) -> 2.3025851 | E6: =A6-AVERAGE($A$2:$A$91) -> -5.7222222 | F6: =B6-AVERAGE($B$2:$B$91) -> -52.455556 | G6: =Таблица3[[#This Row],[Z]]-AVERAGE(Таблица3[Z]) -> 3.5111111 | H6: =Таблица3[[#This Row],[ln(Z'')]]-AVERAGE(Таблица3[ln(Z'')]) -> 0.57117702
A7: 30 | B7: 276 | C7: -6 | D7: =LN(Таблица3[[#This Row],[Z]]+exponential!$R$3) -> 1.7917595 | E7: =A7-AVERAGE($A$2:$A$91) -> -5.7222222 | F7: =B7-AVERAGE($B$2:$B$91) -> -50.455556 | G7: =Таблица3[[#This Row],[Z]]-AVERAGE(Таблица3[Z]) -> -0.48888889 | H7: =Таблица3[[#This Row],[ln(Z'')]]-AVERAGE(Таблица3[ln(Z'')]) -> 0.060351401
A8: 32 | B8: 294 | C8: -6 | D8: =LN(Таблица3[[#This Row],[Z]]+exponential!$R$3) -> 1.7917595 | E8: =A8-AVERAGE($A$2:$A$91) -> -3.7222222 | F8: =B8-AVERAGE($B$2:$B$91) -> -32.455556 | G8: =Таблица3[[#This Row],[Z]]-AVERAGE(Таблица3[Z]) -> -0.48888889 | H8: =Таблица3[[#This Row],[ln(Z'')]]-AVERAGE(Таблица3[ln(Z'')]) -> 0.060351401
A9: 38 | B9: 348 | C9: -5 | D9: =LN(Таблица3[[#This Row],[Z]]+exponential!$R$3) -> 1.9459101 | E9: =A9-AVERAGE($A$2:$A$91) -> 2.2777778 | F9: =B9-AVERAGE($B$2:$B$91) -> 21.544444 | G9: =Таблица3[[#This Row],[Z]]-AVERAGE(Таблица3[Z]) -> 0.51111111 | H9: =Таблица3[[#This Row],[ln(Z'')]]-AVERAGE(Таблица3[ln(Z'')]) -> 0.21450208
A10: 34 | B10: 315 | C10: -10 | D10: =LN(Таблица3[[#This Row],[Z]]+exponential!$R$3) -> 0.69314718 | E10: =A10-AVERAGE($A$2:$A$91) -> -1.7222222 | F10: =B10-AVERAGE($B$2:$B$91) -> -11.455556 | G10: =Таблица3[[#This Row],[Z]]-AVERAGE(Таблица3[Z]) -> -4.4888889 | H10: =Таблица3[[#This Row],[ln(Z'')]]-AVERAGE(Таблица3[ln(Z'')]) -> -1.0382609
A11: 34 | B11: 307 | C11: -4 | D11: =LN(Таблица3[[#This Row],[Z]]+exponential!$R$3) -> 2.0794415 | E11: =A11-AVERAGE($A$2:$A$91) -> -1.7222222 | F11: =B11-AVERAGE($B$2:$B$91) -> -19.455556 | G11: =Таблица3[[#This Row],[Z]]-AVERAGE(Таблица3[Z]) -> 1.5111111 | H11: =Таблица3[[#This Row],[ln(Z'')]]-AVERAGE(Таблица3[ln(Z'')]) -> 0.34803347
A12: 41 | B12: 377 | C12: -9 | D12: =LN(Таблица3[[#This Row],[Z]]+exponential!$R$3) -> 1.0986123 | E12: =A12-AVERAGE($A$2:$A$91) -> 5.2777778 | F12: =B12-AVERAGE($B$2:$B$91) -> 50.544444 | G12: =Таблица3[[#This Row],[Z]]-AVERAGE(Таблица3[Z]) -> -3.4888889 | H12: =Таблица3[[#This Row],[ln(Z'')]]-AVERAGE(Таблица3[ln(Z'')]) -> -0.63279578
A13: 37 | B13: 338 | C13: -5 | D13: =LN(Таблица3[[#This Row],[Z]]+exponential!$R$3) -> 1.9459101 | E13: =A13-AVERAGE($A$2:$A$91) -> 1.2777778 | F13: =B13-AVERAGE($B$2:$B$91) -> 11.544444 | G13: =Таблица3[[#This Row],[Z]]-AVERAGE(Таблица3[Z]) -> 0.51111111 | H13: =Таблица3[[#This Row],[ln(Z'')]]-AVERAGE(Таблица3[ln(Z'')]) -> 0.21450208
A14: 39 | B14: 353 | C14: -7 | D14: =LN(Таблица3[[#This Row],[Z]]+exponential!$R$3) -> 1.6094379 | E14: =A14-AVERAGE($A$2:$A$91) -> 3.2777778 | F14: =B14-AVERAGE($B$2:$B$91) -> 26.544444 | G14: =Таблица3[[#This Row],[Z]]-AVERAGE(Таблица3[Z]) -> -1.4888889 | H14: =Таблица3[[#This Row],[ln(Z'')]]-AVERAGE(Таблица3[ln(Z'')]) -> -0.12197016
A15: 36 | B15: 332 | C15: -3 | D15: =LN(Таблица3[[#This Row],[Z]]+exponential!$R$3) -> 2.1972246 | E15: =A15-AVERAGE($A$2:$A$91) -> 0.27777778 | F15: =B15-AVERAGE($B$2:$B$91) -> 5.5444444 | G15: =Таблица3[[#This Row],[Z]]-AVERAGE(Таблица3[Z]) -> 2.5111111 | H15: =Таблица3[[#This Row],[ln(Z'')]]-AVERAGE(Таблица3[ln(Z'')]) -> 0.46581651
A16: 34 | B16: 307 | C16: -10 | D16: =LN(Таблица3[[#This Row],[Z]]+exponential!$R$3) -> 0.69314718 | E16: =A16-AVERAGE($A$2:$A$91) -> -1.7222222 | F16: =B16-AVERAGE($B$2:$B$91) -> -19.455556 | G16: =Таблица3[[#This Row],[Z]]-AVERAGE(Таблица3[Z]) -> -4.4888889 | H16: =Таблица3[[#This Row],[ln(Z'')]]-AVERAGE(Таблица3[ln(Z'')]) -> -1.0382609
A17: 29 | B17: 264 | C17: -1 | D17: =LN(Таблица3[[#This Row],[Z]]+exponential!$R$3) -> 2.3978953 | E17: =A17-AVERAGE($A$2:$A$91) -> -6.7222222 | F17: =B17-AVERAGE($B$2:$B$91) -> -62.455556 | G17: =Таблица3[[#This Row],[Z]]-AVERAGE(Таблица3[Z]) -> 4.5111111 | H17: =Таблица3[[#This Row],[ln(Z'')]]-AVERAGE(Таблица3[ln(Z'')]) -> 0.6664872
... A91: 35 | B91: 324 | C91: -10 | D91: =LN(Таблица3[[#This Row],[Z]]+exponential!$R$3) -> 0.69314718 | E91: =A91-AVERAGE($A$2:$A$91) -> -0.72222222 | F91: =B91-AVERAGE($B$2:$B$91) -> -2.4555556 | G91: =Таблица3[[#This Row],[Z]]-AVERAGE(Таблица3[Z]) -> -4.4888889 | H91: =Таблица3[[#This Row],[ln(Z'')]]-AVERAGE(Таблица3[ln(Z'')]) -> -1.0382609

Sheet exponential
A1: N | B1: X | C1: Y | D1: Z | E1: Смещённая Z' | F1: ln(X) | G1: ln(Y) | H1: ln(|Z'|) | I1: ln(X)*ln(Y) | J1: ln(X)*ln(|Z'|) | K1: ln(Y)*ln(|Z'|) | L1: Предсказанные значения ln(Z') | M1: Предсказанные значения Z | N1: Нормированные остатки для Z | O1: Остатки | P1: Нормированные остатки | Q1: Экспоненциальная модель сводится к линейной смещением и логарифмированием
A2: 1 | B2: 25 | C2: 233 | D2: -7 | E2: =Таблица4[[#This Row],[Z]]+$R$3 -> 5 | F2: =LN(ABS(B2)) -> 3.2188758 | G2: =LN(ABS(C2)) -> 5.4510385 | H2: =LN(ABS(E2)) -> 1.6094379 | I2: =F2*G2 -> 17.546216 | J2: =F2*H2 -> 5.1805808 | K2: =G2*H2 -> 8.7731079 | L2: =$R$10+$R$11*Таблица4[[#This Row],[ln(X)]]+$R$12*Таблица4[[#This Row],[ln(Y)]] -> 1.6804506 | M2: =EXP($R$10)*Таблица4[[#This Row],[X]]^$R$11*Таблица4[[#This Row],[Y]]^$R$12-$R$3 -> -6.6320258 | N2: =ABS((Таблица4[[#This Row],[Предсказанные значения Z]]-Таблица4[[#This Row],[Z]])/Таблица4[[#This Row],[Z]]) -> 0.052567739 | O2: =ABS(Таблица4[[#This Row],[ln(|Z''|)]]-Таблица4[[#This Row],[Предсказанные значения ln(Z'')]]) -> 0.071012676 | P2: =ABS(Таблица4[[#This Row],[Остатки]]/Таблица4[[#This Row],[ln(|Z''|)]]) -> 0.044122656
A3: 2 | B3: 47 | C3: 432 | D3: -6 | E3: =Таблица4[[#This Row],[Z]]+$R$3 -> 6 | F3: =LN(ABS(B3)) -> 3.8501476 | G3: =LN(ABS(C3)) -> 6.0684256 | H3: =LN(ABS(E3)) -> 1.7917595 | I3: =F3*G3 -> 23.364334 | J3: =F3*H3 -> 6.8985384 | K3: =G3*H3 -> 10.873159 | L3: =$R$10+$R$11*Таблица4[[#This Row],[ln(X)]]+$R$12*Таблица4[[#This Row],[ln(Y)]] -> 1.6072416 | M3: =EXP($R$10)*Таблица4[[#This Row],[X]]^$R$11*Таблица4[[#This Row],[Y]]^$R$12-$R$3 -> -7.0109695 | N3: =ABS((Таблица4[[#This Row],[Предсказанные значения Z]]-Таблица4[[#This Row],[Z]])/Таблица4[[#This Row],[Z]]) -> 0.16849491 | O3: =ABS(Таблица4[[#This Row],[ln(|Z''|)]]-Таблица4[[#This Row],[Предсказанные значения ln(Z'')]]) -> 0.18451786 | P3: =ABS(Таблица4[[#This Row],[Остатки]]/Таблица4[[#This Row],[ln(|Z''|)]]) -> 0.10298138 | Q3: c | R3: =-MIN(Таблица4[Z])+2 -> 12
A4: 3 | B4: 42 | C4: 385 | D4: -10 | E4: =Таблица4[[#This Row],[Z]]+$R$3 -> 2 | F4: =LN(ABS(B4)) -> 3.7376696 | G4: =LN(ABS(C4)) -> 5.9532433 | H4: =LN(ABS(E4)) -> 0.69314718 | I4: =F4*G4 -> 22.251257 | J4: =F4*H4 -> 2.5907552 | K4: =G4*H4 -> 4.1264738 | L4: =$R$10+$R$11*Таблица4[[#This Row],[ln(X)]]+$R$12*Таблица4[[#This Row],[ln(Y)]] -> 1.6600802 | M4: =EXP($R$10)*Таблица4[[#This Row],[X]]^$R$11*Таблица4[[#This Row],[Y]]^$R$12-$R$3 -> -6.7402676 | N4: =ABS((Таблица4[[#This Row],[Предсказанные значения Z]]-Таблица4[[#This Row],[Z]])/Таблица4[[#This Row],[Z]]) -> 0.32597324 | O4: =ABS(Таблица4[[#This Row],[ln(|Z''|)]]-Таблица4[[#This Row],[Предсказанные значения ln(Z'')]]) -> 0.96693297 | P4: =ABS(Таблица4[[#This Row],[Остатки]]/Таблица4[[#This Row],[ln(|Z''|)]]) -> 1.3949894 | Q4: Получающаяся система уравнений на коэффициенты
A5: 4 | B5: 38 | C5: 347 | D5: -1 | E5: =Таблица4[[#This Row],[Z]]+$R$3 -> 11 | F5: =LN(ABS(B5)) -> 3.6375862 | G5: =LN(ABS(C5)) -> 5.8493248 | H5: =LN(ABS(E5)) -> 2.3978953 | I5: =F5*G5 -> 21.277423 | J5: =F5*H5 -> 8.7225507 | K5: =G5*H5 -> 14.026068 | L5: =$R$10+$R$11*Таблица4[[#This Row],[ln(X)]]+$R$12*Таблица4[[#This Row],[ln(Y)]] -> 1.7180766 | M5: =EXP($R$10)*Таблица4[[#This Row],[X]]^$R$11*Таблица4[[#This Row],[Y]]^$R$12-$R$3 -> -6.4262022 | N5: =ABS((Таблица4[[#This Row],[Предсказанные значения Z]]-Таблица4[[#This Row],[Z]])/Таблица4[[#This Row],[Z]]) -> 5.4262022 | O5: =ABS(Таблица4[[#This Row],[ln(|Z''|)]]-Таблица4[[#This Row],[Предсказанные значения ln(Z'')]]) -> 0.67981862 | P5: =ABS(Таблица4[[#This Row],[Остатки]]/Таблица4[[#This Row],[ln(|Z''|)]]) -> 0.28350639
A6: 5 | B6: 30 | C6: 274 | D6: -2 | E6: =Таблица4[[#This Row],[Z]]+$R$3 -> 10 | F6: =LN(ABS(B6)) -> 3.4011974 | G6: =LN(ABS(C6)) -> 5.6131281 | H6: =LN(ABS(E6)) -> 2.3025851 | I6: =F6*G6 -> 19.091357 | J6: =F6*H6 -> 7.8315464 | K6: =G6*H6 -> 12.924705 | L6: =$R$10+$R$11*Таблица4[[#This Row],[ln(X)]]+$R$12*Таблица4[[#This Row],[ln(Y)]] -> 1.7839711 | M6: =EXP($R$10)*Таблица4[[#This Row],[X]]^$R$11*Таблица4[[#This Row],[Y]]^$R$12-$R$3 -> -6.0465486 | N6: =ABS((Таблица4[[#This Row],[Предсказанные значения Z]]-Таблица4[[#This Row],[Z]])/Таблица4[[#This Row],[Z]]) -> 2.0232743 | O6: =ABS(Таблица4[[#This Row],[ln(|Z''|)]]-Таблица4[[#This Row],[Предсказанные значения ln(Z'')]]) -> 0.51861397 | P6: =ABS(Таблица4[[#This Row],[Остатки]]/Таблица4[[#This Row],[ln(|Z''|)]]) -> 0.22523118
A7: 6 | B7: 30 | C7: 276 | D7: -6 | E7: =Таблица4[[#This Row],[Z]]+$R$3 -> 6 | F7: =LN(ABS(B7)) -> 3.4011974 | G7: =LN(ABS(C7)) -> 5.6204009 | H7: =LN(ABS(E7)) -> 1.7917595 | I7: =F7*G7 -> 19.116093 | J7: =F7*H7 -> 6.0941276 | K7: =G7*H7 -> 10.070406 | L7: =$R$10+$R$11*Таблица4[[#This Row],[ln(X)]]+$R$12*Таблица4[[#This Row],[ln(Y)]] -> 1.72808 | M7: =EXP($R$10)*Таблица4[[#This Row],[X]]^$R$11*Таблица4[[#This Row],[Y]]^$R$12-$R$3 -> -6.3701659 | N7: =ABS((Таблица4[[#This Row],[Предсказанные значения Z]]-Таблица4[[#This Row],[Z]])/Таблица4[[#This Row],[Z]]) -> 0.06169432 | O7: =ABS(Таблица4[[#This Row],[ln(|Z''|)]]-Таблица4[[#This Row],[Предсказанные значения ln(Z'')]]) -> 0.063679498 | P7: =ABS(Таблица4[[#This Row],[Остатки]]/Таблица4[[#This Row],[ln(|Z''|)]]) -> 0.035540205
A8: 7 | B8: 32 | C8: 294 | D8: -6 | E8: =Таблица4[[#This Row],[Z]]+$R$3 -> 6 | F8: =LN(ABS(B8)) -> 3.4657359 | G8: =LN(ABS(C8)) -> 5.6835798 | H8: =LN(ABS(E8)) -> 1.7917595 | I8: =F8*G8 -> 19.697786 | J8: =F8*H8 -> 6.2097651 | K8: =G8*H8 -> 10.183608 | L8: =$R$10+$R$11*Таблица4[[#This Row],[ln(X)]]+$R$12*Таблица4[[#This Row],[ln(Y)]] -> 1.7201352 | M8: =EXP($R$10)*Таблица4[[#This Row],[X]]^$R$11*Таблица4[[#This Row],[Y]]^$R$12-$R$3 -> -6.4147166 | N8: =ABS((Таблица4[[#This Row],[Предсказанные значения Z]]-Таблица4[[#This Row],[Z]])/Таблица4[[#This Row],[Z]]) -> 0.069119439 | O8: =ABS(Таблица4[[#This Row],[ln(|Z''|)]]-Таблица4[[#This Row],[Предсказанные значения ln(Z'')]]) -> 0.071624301 | P8: =ABS(Таблица4[[#This Row],[Остатки]]/Таблица4[[#This Row],[ln(|Z''|)]]) -> 0.039974283
A9: 8 | B9: 38 | C9: 348 | D9: -5 | E9: =Таблица4[[#This Row],[Z]]+$R$3 -> 7 | F9: =LN(ABS(B9)) -> 3.6375862 | G9: =LN(ABS(C9)) -> 5.8522025 | H9: =LN(ABS(E9)) -> 1.9459101 | I9: =F9*G9 -> 21.287891 | J9: =F9*H9 -> 7.0784158 | K9: =G9*H9 -> 11.38786 | L9: =$R$10+$R$11*Таблица4[[#This Row],[ln(X)]]+$R$12*Таблица4[[#This Row],[ln(Y)]] -> 1.6959615 | M9: =EXP($R$10)*Таблица4[[#This Row],[X]]^$R$11*Таблица4[[#This Row],[Y]]^$R$12-$R$3 -> -6.5481144 | N9: =ABS((Таблица4[[#This Row],[Предсказанные значения Z]]-Таблица4[[#This Row],[Z]])/Таблица4[[#This Row],[Z]]) -> 0.30962289 | O9: =ABS(Таблица4[[#This Row],[ln(|Z''|)]]-Таблица4[[#This Row],[Предсказанные значения ln(Z'')]]) -> 0.24994862 | P9: =ABS(Таблица4[[#This Row],[Остатки]]/Таблица4[[#This Row],[ln(|Z''|)]]) -> 0.12844818 | Q9: Коэффициенты | R9: Значения
A10: 9 | B10: 34 | C10: 315 | D10: -10 | E10: =Таблица4[[#This Row],[Z]]+$R$3 -> 2 | F10: =LN(ABS(B10)) -> 3.5263605 | G10: =LN(ABS(C10)) -> 5.7525726 | H10: =LN(ABS(E10)) -> 0.69314718 | I10: =F10*G10 -> 20.285645 | J10: =F10*H10 -> 2.4442869 | K10: =G10*H10 -> 3.9873795 | L10: =$R$10+$R$11*Таблица4[[#This Row],[ln(X)]]+$R$12*Таблица4[[#This Row],[ln(Y)]] -> 1.6385472 | M10: =EXP($R$10)*Таблица4[[#This Row],[X]]^$R$11*Таблица4[[#This Row],[Y]]^$R$12-$R$3 -> -6.8523147 | N10: =ABS((Таблица4[[#This Row],[Предсказанные значения Z]]-Таблица4[[#This Row],[Z]])/Таблица4[[#This Row],[Z]]) -> 0.31476853 | O10: =ABS(Таблица4[[#This Row],[ln(|Z''|)]]-Таблица4[[#This Row],[Предсказанные значения ln(Z'')]]) -> 0.94539997 | P10: =ABS(Таблица4[[#This Row],[Остатки]]/Таблица4[[#This Row],[ln(|Z''|)]]) -> 1.3639239 | Q10: ln(b0) | R10: 19.752
A11: 10 | B11: 34 | C11: 307 | D11: -4 | E11: =Таблица4[[#This Row],[Z]]+$R$3 -> 8 | F11: =LN(ABS(B11)) -> 3.5263605 | G11: =LN(ABS(C11)) -> 5.7268477 | H11: =LN(ABS(E11)) -> 2.0794415 | I11: =F11*G11 -> 20.19493 | J11: =F11*H11 -> 7.3328606 | K11: =G11*H11 -> 11.908645 | L11: =$R$10+$R$11*Таблица4[[#This Row],[ln(X)]]+$R$12*Таблица4[[#This Row],[ln(Y)]] -> 1.8362429 | M11: =EXP($R$10)*Таблица4[[#This Row],[X]]^$R$11*Таблица4[[#This Row],[Y]]^$R$12-$R$3 -> -5.7270738 | N11: =ABS((Таблица4[[#This Row],[Предсказанные значения Z]]-Таблица4[[#This Row],[Z]])/Таблица4[[#This Row],[Z]]) -> 0.43176845 | O11: =ABS(Таблица4[[#This Row],[ln(|Z''|)]]-Таблица4[[#This Row],[Предсказанные значения ln(Z'')]]) -> 0.2431986 | P11: =ABS(Таблица4[[#This Row],[Остатки]]/Таблица4[[#This Row],[ln(|Z''|)]]) -> 0.1169538 | Q11: b1 | R11: 7.4
A12: 11 | B12: 41 | C12: 377 | D12: -9 | E12: =Таблица4[[#This Row],[Z]]+$R$3 -> 3 | F12: =LN(ABS(B12)) -> 3.7135721 | G12: =LN(ABS(C12)) -> 5.9322452 | H12: =LN(ABS(E12)) -> 1.0986123 | I12: =F12*G12 -> 22.02982 | J12: =F12*H12 -> 4.0797759 | K12: =G12*H12 -> 6.5172375 | L12: =$R$10+$R$11*Таблица4[[#This Row],[ln(X)]]+$R$12*Таблица4[[#This Row],[ln(Y)]] -> 1.643129 | M12: =EXP($R$10)*Таблица4[[#This Row],[X]]^$R$11*Таблица4[[#This Row],[Y]]^$R$12-$R$3 -> -6.8286746 | N12: =ABS((Таблица4[[#This Row],[Предсказанные значения Z]]-Таблица4[[#This Row],[Z]])/Таблица4[[#This Row],[Z]]) -> 0.24125838 | O12: =ABS(Таблица4[[#This Row],[ln(|Z''|)]]-Таблица4[[#This Row],[Предсказанные значения ln(Z'')]]) -> 0.54451674 | P12: =ABS(Таблица4[[#This Row],[Остатки]]/Таблица4[[#This Row],[ln(|Z''|)]]) -> 0.4956405 | Q12: b2 | R12: -7.685
A13: 12 | B13: 37 | C13: 338 | D13: -5 | E13: =Таблица4[[#This Row],[Z]]+$R$3 -> 7 | F13: =LN(ABS(B13)) -> 3.6109179 | G13: =LN(ABS(C13)) -> 5.8230459 | H13: =LN(ABS(E13)) -> 1.9459101 | I13: =F13*G13 -> 21.026541 | J13: =F13*H13 -> 7.0265218 | K13: =G13*H13 -> 11.331124 | L13: =$R$10+$R$11*Таблица4[[#This Row],[ln(X)]]+$R$12*Таблица4[[#This Row],[ln(Y)]] -> 1.7226848 | M13: =EXP($R$10)*Таблица4[[#This Row],[X]]^$R$11*Таблица4[[#This Row],[Y]]^$R$12-$R$3 -> -6.4004578 | N13: =ABS((Таблица4[[#This Row],[Предсказанные значения Z]]-Таблица4[[#This Row],[Z]])/Таблица4[[#This Row],[Z]]) -> 0.28009156 | O13: =ABS(Таблица4[[#This Row],[ln(|Z''|)]]-Таблица4[[#This Row],[Предсказанные значения ln(Z'')]]) -> 0.2232253 | P13: =ABS(Таблица4[[#This Row],[Остатки]]/Таблица4[[#This Row],[ln(|Z''|)]]) -> 0.11471511
A14: 13 | B14: 39 | C14: 353 | D14: -7 | E14: =Таблица4[[#This Row],[Z]]+$R$3 -> 5 | F14: =LN(ABS(B14)) -> 3.6635616 | G14: =LN(ABS(C14)) -> 5.8664681 | H14: =LN(ABS(E14)) -> 1.6094379 | I14: =F14*G14 -> 21.492167 | J14: =F14*H14 -> 5.896275 | K14: =G14*H14 -> 9.4417161 | L14: =$R$10+$R$11*Таблица4[[#This Row],[ln(X)]]+$R$12*Таблица4[[#This Row],[ln(Y)]] -> 1.7785492 | M14: =EXP($R$10)*Таблица4[[#This Row],[X]]^$R$11*Таблица4[[#This Row],[Y]]^$R$12-$R$3 -> -6.0787406 | N14: =ABS((Таблица4[[#This Row],[Предсказанные значения Z]]-Таблица4[[#This Row],[Z]])/Таблица4[[#This Row],[Z]]) -> 0.13160849 | O14: =ABS(Таблица4[[#This Row],[ln(|Z''|)]]-Таблица4[[#This Row],[Предсказанные значения ln(Z'')]]) -> 0.16911125 | P14: =ABS(Таблица4[[#This Row],[Остатки]]/Таблица4[[#This Row],[ln(|Z''|)]]) -> 0.10507473 | Q14: Средняя ошибка аппроксимации (mae) | R14: =SUM(Таблица4[Нормированные остатки])/COUNT(Таблица4[Нормированные остатки]) -> 0.38155439
A15: 14 | B15: 36 | C15: 332 | D15: -3 | E15: =Таблица4[[#This Row],[Z]]+$R$3 -> 9 | F15: =LN(ABS(B15)) -> 3.5835189 | G15: =LN(ABS(C15)) -> 5.805135 | H15: =LN(ABS(E15)) -> 2.1972246 | I15: =F15*G15 -> 20.802811 | J15: =F15*H15 -> 7.8737959 | K15: =G15*H15 -> 12.755185 | L15: =$R$10+$R$11*Таблица4[[#This Row],[ln(X)]]+$R$12*Таблица4[[#This Row],[ln(Y)]] -> 1.6575779 | M15: =EXP($R$10)*Таблица4[[#This Row],[X]]^$R$11*Таблица4[[#This Row],[Y]]^$R$12-$R$3 -> -6.7534123 | N15: =ABS((Таблица4[[#This Row],[Предсказанные значения Z]]-Таблица4[[#This Row],[Z]])/Таблица4[[#This Row],[Z]]) -> 1.2511374 | O15: =ABS(Таблица4[[#This Row],[ln(|Z''|)]]-Таблица4[[#This Row],[Предсказанные значения ln(Z'')]]) -> 0.53964667 | P15: =ABS(Таблица4[[#This Row],[Остатки]]/Таблица4[[#This Row],[ln(|Z''|)]]) -> 0.24560378 | Q15: Средняя ошибка аппроксимации Z (mae) | R15: =SUM(Таблица4[Нормированные остатки для Z])/COUNT(Таблица4[Нормированные остатки для Z]) -> 1.0694734
A16: 15 | B16: 34 | C16: 307 | D16: -10 | E16: =Таблица4[[#This Row],[Z]]+$R$3 -> 2 | F16: =LN(ABS(B16)) -> 3.5263605 | G16: =LN(ABS(C16)) -> 5.7268477 | H16: =LN(ABS(E16)) -> 0.69314718 | I16: =F16*G16 -> 20.19493 | J16: =F16*H16 -> 2.4442869 | K16: =G16*H16 -> 3.9695484 | L16: =$R$10+$R$11*Таблица4[[#This Row],[ln(X)]]+$R$12*Таблица4[[#This Row],[ln(Y)]] -> 1.8362429 | M16: =EXP($R$10)*Таблица4[[#This Row],[X]]^$R$11*Таблица4[[#This Row],[Y]]^$R$12-$R$3 -> -5.7270738 | N16: =ABS((Таблица4[[#This Row],[Предсказанные значения Z]]-Таблица4[[#This Row],[Z]])/Таблица4[[#This Row],[Z]]) -> 0.42729262 | O16: =ABS(Таблица4[[#This Row],[ln(|Z''|)]]-Таблица4[[#This Row],[Предсказанные значения ln(Z'')]]) -> 1.1430958 | P16: =ABS(Таблица4[[#This Row],[Остатки]]/Таблица4[[#This Row],[ln(|Z''|)]]) -> 1.6491386 | Q16: Коэффициент детерминации | R16: =1-SUMSQ(Таблица4[Остатки])/SUMSQ(Таблица3[Отклонения ln(Z'')]) -> 0.020481086
A17: 16 | B17: 29 | C17: 264 | D17: -1 | E17: =Таблица4[[#This Row],[Z]]+$R$3 -> 11 | F17: =LN(ABS(B17)) -> 3.3672958 | G17: =LN(ABS(C17)) -> 5.5759491 | H17: =LN(ABS(E17)) -> 2.3978953 | I17: =F17*G17 -> 18.77587 | J17: =F17*H17 -> 8.0744228 | K17: =G17*H17 -> 13.370542 | L17: =$R$10+$R$11*Таблица4[[#This Row],[ln(X)]]+$R$12*Таблица4[[#This Row],[ln(Y)]] -> 1.8188203 | M17: =EXP($R$10)*Таблица4[[#This Row],[X]]^$R$11*Таблица4[[#This Row],[Y]]^$R$12-$R$3 -> -5.8354183 | N17: =ABS((Таблица4[[#This Row],[Предсказанные значения Z]]-Таблица4[[#This Row],[Z]])/Таблица4[[#This Row],[Z]]) -> 4.8354183 | O17: =ABS(Таблица4[[#This Row],[ln(|Z''|)]]-Таблица4[[#This Row],[Предсказанные значения ln(Z'')]]) -> 0.57907499 | P17: =ABS(Таблица4[[#This Row],[Остатки]]/Таблица4[[#This Row],[ln(|Z''|)]]) -> 0.24149303
A18: 17 | B18: 31 | C18: 285 | D18: -3 | E18: =Таблица4[[#This Row],[Z]]+$R$3 -> 9 | F18: =LN(ABS(B18)) -> 3.4339872 | G18: =LN(ABS(C18)) -> 5.6524892 | H18: =LN(ABS(E18)) -> 2.1972246 | I18: =F18*G18 -> 19.410576 | J18: =F18*H18 -> 7.5452411 | K18: =G18*H18 -> 12.419788 | L18: =$R$10+$R$11*Таблица4[[#This Row],[ln(X)]]+$R$12*Таблица4[[#This Row],[ln(Y)]] -> 1.724126 | M18: =EXP($R$10)*Таблица4[[#This Row],[X]]^$R$11*Таблица4[[#This Row],[Y]]^$R$12-$R$3 -> -6.3923824 | N18: =ABS((Таблица4[[#This Row],[Предсказанные значения Z]]-Таблица4[[#This Row],[Z]])/Таблица4[[#This Row],[Z]]) -> 1.1307941 | O18: =ABS(Таблица4[[#This Row],[ln(|Z''|)]]-Таблица4[[#This Row],[Предсказанные значения ln(Z'')]]) -> 0.47309861 | P18: =ABS(Таблица4[[#This Row],[Остатки]]/Таблица4[[#This Row],[ln(|Z''|)]]) -> 0.21531646
A19: 18 | B19: 41 | C19: 377 | D19: -5 | E19: =Таблица4[[#This Row],[Z]]+$R$3 -> 7 | F19: =LN(ABS(B19)) -> 3.7135721 | G19: =LN(ABS(C19)) -> 5.9322452 | H19: =LN(ABS(E19)) -> 1.9459101 | I19: =F19*G19 -> 22.02982 | J19: =F19*H19 -> 7.2262776 | K19: =G19*H19 -> 11.543616 | L19: =$R$10+$R$11*Таблица4[[#This Row],[ln(X)]]+$R$12*Таблица4[[#This Row],[ln(Y)]] -> 1.643129 | M19: =EXP($R$10)*Таблица4[[#This Row],[X]]^$R$11*Таблица4[[#This Row],[Y]]^$R$12-$R$3 -> -6.8286746 | N19: =ABS((Таблица4[[#This Row],[Предсказанные значения Z]]-Таблица4[[#This Row],[Z]])/Таблица4[[#This Row],[Z]]) -> 0.36573491 | O19: =ABS(Таблица4[[#This Row],[ln(|Z''|)]]-Таблица4[[#This Row],[Предсказанные значения ln(Z'')]]) -> 0.30278112 | P19: =ABS(Таблица4[[#This Row],[Остатки]]/Таблица4[[#This Row],[ln(|Z''|)]]) -> 0.15559872
A20: 19 | B20: 15 | C20: 137 | D20: -5 | E20: =Таблица4[[#This Row],[Z]]+$R$3 -> 7 | F20: =LN(ABS(B20)) -> 2.7080502 | G20: =LN(ABS(C20)) -> 4.9199809 | H20: =LN(ABS(E20)) -> 1.9459101 | I20: =F20*G20 -> 13.323555 | J20: =F20*H20 -> 5.2696224 | K20: =G20*H20 -> 9.5738408 | L20: =$R$10+$R$11*Таблица4[[#This Row],[ln(X)]]+$R$12*Таблица4[[#This Row],[ln(Y)]] -> 1.9815181 | M20: =EXP($R$10)*Таблица4[[#This Row],[X]]^$R$11*Таблица4[[#This Row],[Y]]^$R$12-$R$3 -> -4.7462537 | N20: =ABS((Таблица4[[#This Row],[Предсказанные значения Z]]-Таблица4[[#This Row],[Z]])/Таблица4[[#This Row],[Z]]) -> 0.05074927 | O20: =ABS(Таблица4[[#This Row],[ln(|Z''|)]]-Таблица4[[#This Row],[Предсказанные значения ln(Z'')]]) -> 0.035607924 | P20: =ABS(Таблица4[[#This Row],[Остатки]]/Таблица4[[#This Row],[ln(|Z''|)]]) -> 0.018298853
A21: 20 | B21: 27 | C21: 245 | D21: -1 | E21: =Таблица4[[#This Row],[Z]]+$R$3 -> 11 | F21: =LN(ABS(B21)) -> 3.2958369 | G21: =LN(ABS(C21)) -> 5.5012582 | H21: =LN(ABS(E21)) -> 2.3978953 | I21: =F21*G21 -> 18.13125 | J21: =F21*H21 -> 7.9030716 | K21: =G21*H21 -> 13.191441 | L21: =$R$10+$R$11*Таблица4[[#This Row],[ln(X)]]+$R$12*Таблица4[[#This Row],[ln(Y)]] -> 1.8640235 | M21: =EXP($R$10)*Таблица4[[#This Row],[X]]^$R$11*Таблица4[[#This Row],[Y]]^$R$12-$R$3 -> -5.5503655 | N21: =ABS((Таблица4[[#This Row],[Предсказанные значения Z]]-Таблица4[[#This Row],[Z]])/Таблица4[[#This Row],[Z]]) -> 4.5503655 | O21: =ABS(Таблица4[[#This Row],[ln(|Z''|)]]-Таблица4[[#This Row],[Предсказанные значения ln(Z'')]]) -> 0.53387181 | P21: =ABS(Таблица4[[#This Row],[Остатки]]/Таблица4[[#This Row],[ln(|Z''|)]]) -> 0.22264184
A22: 21 | B22: 46 | C22: 421 | D22: 1 | E22: =Таблица4[[#This Row],[Z]]+$R$3 -> 13 | F22: =LN(ABS(B22)) -> 3.8286414 | G22: =LN(ABS(C22)) -> 6.0426328 | H22: =LN(ABS(E22)) -> 2.5649494 | I22: =F22*G22 -> 23.135074 | J22: =F22*H22 -> 9.8202713 | K22: =G22*H22 -> 15.499047 | L22: =$R$10+$R$11*Таблица4[[#This Row],[ln(X)]]+$R$12*Таблица4[[#This Row],[ln(Y)]] -> 1.646313 | M22: =EXP($R$10)*Таблица4[[#This Row],[X]]^$R$11*Таблица4[[#This Row],[Y]]^$R$12-$R$3 -> -6.8121829 | N22: =ABS((Таблица4[[#This Row],[Предсказанные значения Z]]-Таблица4[[#This Row],[Z]])/Таблица4[[#This Row],[Z]]) -> 7.8121829 | O22: =ABS(Таблица4[[#This Row],[ln(|Z''|)]]-Таблица4[[#This Row],[Предсказанные значения ln(Z'')]]) -> 0.91863635 | P22: =ABS(Таблица4[[#This Row],[Остатки]]/Таблица4[[#This Row],[ln(|Z''|)]]) -> 0.3581499
A23: 22 | B23: 34 | C23: 313 | D23: -10 | E23: =Таблица4[[#This Row],[Z]]+$R$3 -> 2 | F23: =LN(ABS(B23)) -> 3.5263605 | G23: =LN(ABS(C23)) -> 5.7462032 | H23: =LN(ABS(E23)) -> 0.69314718 | I23: =F23*G23 -> 20.263184 | J23: =F23*H23 -> 2.4442869 | K23: =G23*H23 -> 3.9829645 | L23: =$R$10+$R$11*Таблица4[[#This Row],[ln(X)]]+$R$12*Таблица4[[#This Row],[ln(Y)]] -> 1.6874964 | M23: =EXP($R$10)*Таблица4[[#This Row],[X]]^$R$11*Таблица4[[#This Row],[Y]]^$R$12-$R$3 -> -6.5940707 | N23: =ABS((Таблица4[[#This Row],[Предсказанные значения Z]]-Таблица4[[#This Row],[Z]])/Таблица4[[#This Row],[Z]]) -> 0.34059293 | O23: =ABS(Таблица4[[#This Row],[ln(|Z''|)]]-Таблица4[[#This Row],[Предсказанные значения ln(Z'')]]) -> 0.99434918 | P23: =ABS(Таблица4[[#This Row],[Остатки]]/Таблица4[[#This Row],[ln(|Z''|)]]) -> 1.4345426
A24: 23 | B24: 39 | C24: 359 | D24: -3 | E24: =Таблица4[[#This Row],[Z]]+$R$3 -> 9 | F24: =LN(ABS(B24)) -> 3.6635616 | G24: =LN(ABS(C24)) -> 5.8833224 | H24: =LN(ABS(E24)) -> 2.1972246 | I24: =F24*G24 -> 21.553914 | J24: =F24*H24 -> 8.0496677 | K24: =G24*H24 -> 12.926981 | L24: =$R$10+$R$11*Таблица4[[#This Row],[ln(X)]]+$R$12*Таблица4[[#This Row],[ln(Y)]] -> 1.6490236 | M24: =EXP($R$10)*Таблица4[[#This Row],[X]]^$R$11*Таблица4[[#This Row],[Y]]^$R$12-$R$3 -> -6.7981017 | N24: =ABS((Таблица4[[#This Row],[Предсказанные значения Z]]-Таблица4[[#This Row],[Z]])/Таблица4[[#This Row],[Z]]) -> 1.2660339 | O24: =ABS(Таблица4[[#This Row],[ln(|Z''|)]]-Таблица4[[#This Row],[Предсказанные значения ln(Z'')]]) -> 0.54820095 | P24: =ABS(Таблица4[[#This Row],[Остатки]]/Таблица4[[#This Row],[ln(|Z''|)]]) -> 0.24949701
A25: 24 | B25: 49 | C25: 443 | D25: -9 | E25: =Таблица4[[#This Row],[Z]]+$R$3 -> 3 | F25: =LN(ABS(B25)) -> 3.8918203 | G25: =LN(ABS(C25)) -> 6.0935698 | H25: =LN(ABS(E25)) -> 1.0986123 | I25: =F25*G25 -> 23.715079 | J25: =F25*H25 -> 4.2756016 | K25: =G25*H25 -> 6.6944706 | L25: =$R$10+$R$11*Таблица4[[#This Row],[ln(X)]]+$R$12*Таблица4[[#This Row],[ln(Y)]] -> 1.7223865 | M25: =EXP($R$10)*Таблица4[[#This Row],[X]]^$R$11*Таблица4[[#This Row],[Y]]^$R$12-$R$3 -> -6.402128 | N25: =ABS((Таблица4[[#This Row],[Предсказанные значения Z]]-Таблица4[[#This Row],[Z]])/Таблица4[[#This Row],[Z]]) -> 0.28865244 | O25: =ABS(Таблица4[[#This Row],[ln(|Z''|)]]-Таблица4[[#This Row],[Предсказанные значения ln(Z'')]]) -> 0.62377423 | P25: =ABS(Таблица4[[#This Row],[Остатки]]/Таблица4[[#This Row],[ln(|Z''|)]]) -> 0.56778378
A26: 25 | B26: 22 | C26: 201 | D26: -6 | E26: =Таблица4[[#This Row],[Z]]+$R$3 -> 6 | F26: =LN(ABS(B26)) -> 3.0910425 | G26: =LN(ABS(C26)) -> 5.3033049 | H26: =LN(ABS(E26)) -> 1.7917595 | I26: =F26*G26 -> 16.392741 | J26: =F26*H26 -> 5.5384046 | K26: =G26*H26 -> 9.5022468 | L26: =$R$10+$R$11*Таблица4[[#This Row],[ln(X)]]+$R$12*Таблица4[[#This Row],[ln(Y)]] -> 1.8698159 | M26: =EXP($R$10)*Таблица4[[#This Row],[X]]^$R$11*Таблица4[[#This Row],[Y]]^$R$12-$R$3 -> -5.5128977 | N26: =ABS((Таблица4[[#This Row],[Предсказанные значения Z]]-Таблица4[[#This Row],[Z]])/Таблица4[[#This Row],[Z]]) -> 0.081183708 | O26: =ABS(Таблица4[[#This Row],[ln(|Z''|)]]-Таблица4[[#This Row],[Предсказанные значения ln(Z'')]]) -> 0.078056467 | P26: =ABS(Таблица4[[#This Row],[Остатки]]/Таблица4[[#This Row],[ln(|Z''|)]]) -> 0.043564144
A27: 26 | B27: 48 | C27: 440 | D27: -2 | E27: =Таблица4[[#This Row],[Z]]+$R$3 -> 10 | F27: =LN(ABS(B27)) -> 3.871201 | G27: =LN(ABS(C27)) -> 6.0867747 | H27: =LN(ABS(E27)) -> 2.3025851 | I27: =F27*G27 -> 23.563128 | J27: =F27*H27 -> 8.9137697 | K27: =G27*H27 -> 14.015317 | L27: =$R$10+$R$11*Таблица4[[#This Row],[ln(X)]]+$R$12*Таблица4[[#This Row],[ln(Y)]] -> 1.6220237 | M27: =EXP($R$10)*Таблица4[[#This Row],[X]]^$R$11*Таблица4[[#This Row],[Y]]^$R$12-$R$3 -> -6.9366734 | N27: =ABS((Таблица4[[#This Row],[Предсказанные значения Z]]-Таблица4[[#This Row],[Z]])/Таблица4[[#This Row],[Z]]) -> 2.4683367 | O27: =ABS(Таблица4[[#This Row],[ln(|Z''|)]]-Таблица4[[#This Row],[Предсказанные значения ln(Z'')]]) -> 0.68056139 | P27: =ABS(Таблица4[[#This Row],[Остатки]]/Таблица4[[#This Row],[ln(|Z''|)]]) -> 0.29556406
A28: 27 | B28: 30 | C28: 274 | D28: -2 | E28: =Таблица4[[#This Row],[Z]]+$R$3 -> 10 | F28: =LN(ABS(B28)) -> 3.4011974 | G28: =LN(ABS(C28)) -> 5.6131281 | H28: =LN(ABS(E28)) -> 2.3025851 | I28: =F28*G28 -> 19.091357 | J28: =F28*H28 -> 7.8315464 | K28: =G28*H28 -> 12.924705 | L28: =$R$10+$R$11*Таблица4[[#This Row],[ln(X)]]+$R$12*Таблица4[[#This Row],[ln(Y)]] -> 1.7839711 | M28: =EXP($R$10)*Таблица4[[#This Row],[X]]^$R$11*Таблица4[[#This Row],[Y]]^$R$12-$R$3 -> -6.0465486 | N28: =ABS((Таблица4[[#This Row],[Предсказанные значения Z]]-Таблица4[[#This Row],[Z]])/Таблица4[[#This Row],[Z]]) -> 2.0232743 | O28: =ABS(Таблица4[[#This Row],[ln(|Z''|)]]-Таблица4[[#This Row],[Предсказанные значения ln(Z'')]]) -> 0.51861397 | P28: =ABS(Таблица4[[#This Row],[Остатки]]/Таблица4[[#This Row],[ln(|Z''|)]]) -> 0.22523118
... A91: 90 | B91: 35 | C91: 324 | D91: -10 | E91: =Таблица4[[#This Row],[Z]]+$R$3 -> 2 | F91: =LN(ABS(B91)) -> 3.5553481 | G91: =LN(ABS(C91)) -> 5.7807435 | H91: =LN(ABS(E91)) -> 0.69314718 | I91: =F91*G91 -> 20.552555 | J91: =F91*H91 -> 2.4643795 | K91: =G91*H91 -> 4.0069061 | L91: =$R$10+$R$11*Таблица4[[#This Row],[ln(X)]]+$R$12*Таблица4[[#This Row],[ln(Y)]] -> 1.6365617 | M91: =EXP($R$10)*Таблица4[[#This Row],[X]]^$R$11*Таблица4[[#This Row],[Y]]^$R$12-$R$3 -> -6.8625249 | N91: =ABS((Таблица4[[#This Row],[Предсказанные значения Z]]-Таблица4[[#This Row],[Z]])/Таблица4[[#This Row],[Z]]) -> 0.31374751 | O91: =ABS(Таблица4[[#This Row],[ln(|Z''|)]]-Таблица4[[#This Row],[Предсказанные значения ln(Z'')]]) -> 0.94341456 | P91: =ABS(Таблица4[[#This Row],[Остатки]]/Таблица4[[#This Row],[ln(|Z''|)]]) -> 1.3610595
A92: Сумма | E92: =SUM(F2:F91) -> 318.80765 | F92: =SUM(G2:G91) -> 518.01165 | G92: =SUM(H2:H91) -> 155.82673 | H92: =SUM(I2:I91) -> 1841.3015 | I92: =SUM(J2:J91) -> 550.82216 | J92: =SUM(K2:K91) -> 895.69263 | K92: =SUM(M2:M91) -> -569.30807
A93: Сумма квадратов | E93: =SUMSQ(F2:F91) -> 1135.747 | F93: =SUMSQ(G2:G91) -> 2987.7772 | G93: =SUMSQ(H2:H91) -> 298.35915

Sheet D
A1: N | B1: F1 | C1: F2 | D1: F3 | E1: F4 | F1: F5 | G1: F6 | H1: F7 | J1: Квадратная общая сумма | K1: =SUM(Таблица5[[#Totals],[F1]:[F7]])^2 -> 4100625
A2: 1 | B2: 71 | C2: 71 | D2: 83 | E2: 70 | F2: 70 | G2: 70 | H2: 84 | J2: Общая сумма квадратов | K2: =SUM(B7:H7) -> 147333
A3: 2 | B3: 75 | C3: 72 | D3: 77 | E3: 79 | F3: 63 | G3: 72 | H3: 75 | J3: n | K3: 4
A4: 3 | B4: 79 | C4: 75 | D4: 66 | E4: 71 | F4: 77 | G4: 68 | H4: 69 | J4: m | K4: 7
A5: 4 | B5: 72 | C5: 61 | D5: 76 | E5: 77 | F5: 62 | G5: 67 | H5: 73 | J5: nm | K5: =K3*K4 -> 28
A6: Сумма | B6: =SUM(Таблица5[F1]) -> 297 | C6: =SUM(Таблица5[F2]) -> 279 | D6: =SUM(Таблица5[F3]) -> 302 | E6: =SUM(Таблица5[F4]) -> 297 | F6: =SUM(Таблица5[F5]) -> 272 | G6: =SUM(Таблица5[F6]) -> 277 | H6: =SUM(Таблица5[F7]) -> 301 | J6: a | K6: 0.05
A7: Сумма квадратов | B7: =SUMSQ(Таблица5[F1]) -> 22091 | C7: =SUMSQ(Таблица5[F2]) -> 19571 | D7: =SUMSQ(Таблица5[F3]) -> 22950 | E7: =SUMSQ(Таблица5[F4]) -> 22111 | F7: =SUMSQ(Таблица5[F5]) -> 18642 | G7: =SUMSQ(Таблица5[F6]) -> 19197 | H7: =SUMSQ(Таблица5[F7]) -> 22771
A9: Q | B9: =K2-K1/K5 -> 882.10714
A10: Q1 | B10: =SUMSQ(Таблица5[[#Totals],[F1]:[F7]])/K3-K1/K5 -> 243.35714
A11: Q2 | B11: =B9-B10 -> 638.75
A12: S^2 | B12: =B9/(K5-1) -> 32.670635
A13: S_1^2 | B13: =B10/(K4-1) -> 40.559524
A14: S_2^2 | B14: =B11/(K4*(K3-1)) -> 30.416667
A15: F-статистика | B15: =B13/B14 -> 1.3334638
A16: F-критическое | B16: =FINV(K6,K3,(K3-1)*K4) -> 2.8400998
A18: Принимаем гипотезу о равенстве средних значений при одинаковом количестве элементов на всех уровнях на уровне значимости alpha=a=0.05

Sheet E
A1: N | B1: F1 | C1: F2 | D1: F3 | E1: F4 | F1: n | G1: m | H1: alpha
A2: 1 | B2: 147 | C2: 148 | D2: 176 | E2: 171 | F2: =SUM(B8:E8) -> 18 | G2: 4 | H2: 0.01
A3: 2 | B3: 178 | C3: 162 | D3: 123 | E3: 173
A4: 3 | B4: 166 | C4: 164 | D4: 176 | E4: 172
A5: 4 | D5: 153 | E5: 173
A6: 5 | D6: 131 | E6: 171
A7: 6 | D7: 147 | E7: 154
A8: Количество | B8: 3 | C8: 3 | D8: 6 | E8: 6
A9: Сумма | B9: =SUM(B2:B7) -> 491 | C9: =SUM(C2:C7) -> 474 | D9: =SUM(D2:D7) -> 906 | E9: =SUM(E2:E7) -> 1014 | F9: =SUM(B9:E9)^2 -> 8323225 | G9: Квадрат общей суммы
A10: Сумма квадратов | B10: =SUMSQ(B2:B7) -> 80849 | C10: =SUMSQ(C2:C7) -> 75044 | D10: =SUMSQ(D2:D7) -> 139260 | E10: =SUMSQ(E2:E7) -> 171640 | F10: =SUM(B10:E10) -> 466793 | G10: Общая сумма квадратов
A11: Q | B11: =F10-F9/F2 -> 4391.6111
A12: Q1 | B12: {=SUMPRODUCT(1/B8:E8,B9:E9,B9:E9)-F9/F2} -> 1022.9444
A13: Q2 | B13: =B11-B12 -> 3368.6667
A14: S^2 | B14: =B11/(F2-1) -> 258.33007
A15: S_1^2 | B15: =B12/(G2-1) -> 340.98148
A16: S_2^2 | B16: =B13/(F2-G2) -> 240.61905
A17: F-статистика | B17: =B15/B16 -> 1.417101
A18: F-критическое | B18: =FINV(H2,G2-1,F2-G2) -> 5.5638858
A20: Принимаем гипотезу о равенстве средних значений при неодинаковом количестве элементов на всех уровнях на уровне значимости 0.01
