Workbook
Name Xval: linear_xz!$A$2:$A$91
Name Yval: linear_yz!$A$2:$A$91
Name Zval: linear_xz!$B$2:$B$91

Sheet linear_xz
A1: X | B1: Z | C1: Предсказанные значения | D1: Остатки | E1: Нормированные остатки | F1: Шаг остатка | G1: Коэффициенты | H1: Значения | I1: Выводы
A2: 25 | B2: -7 | C2: =$H$3+$H$2*A2 -> -5.5206501 | D2: =ABS(Таблица1[[#This Row],[Предсказанные значения]]-Таблица1[[#This Row],[Z]]) -> 1.4793499 | E2: =ABS(Таблица1[[#This Row],[Остатки]]/Таблица1[[#This Row],[Z]]) -> 0.2113357 | F2: =Таблица1[[#This Row],[Нормированные остатки]]-E3 -> 0.12818202 | G2: a | H2: 0.00088964438 | I2: В начальный момент предсказанное значение Z было равно а
A3: 47 | B3: -6 | C3: =$H$3+$H$2*A3 -> -5.5010779 | D3: =ABS(Таблица1[[#This Row],[Предсказанные значения]]-Таблица1[[#This Row],[Z]]) -> 0.4989221 | E3: =ABS(Таблица1[[#This Row],[Остатки]]/Таблица1[[#This Row],[Z]]) -> 0.083153683 | F3: =Таблица1[[#This Row],[Нормированные остатки]]-E4 -> -0.3662937 | G3: b | H3: -5.5428912 | I3: При шаге в одну единицу Z в среднем изменяется на b
A4: 42 | B4: -10 | C4: =$H$3+$H$2*A4 -> -5.5055261 | D4: =ABS(Таблица1[[#This Row],[Предсказанные значения]]-Таблица1[[#This Row],[Z]]) -> 4.4944739 | E4: =ABS(Таблица1[[#This Row],[Остатки]]/Таблица1[[#This Row],[Z]]) -> 0.44944739 | F4: =Таблица1[[#This Row],[Нормированные остатки]]-E5 -> -4.0596373
A5: 38 | B5: -1 | C5: =$H$3+$H$2*A5 -> -5.5090847 | D5: =ABS(Таблица1[[#This Row],[Предсказанные значения]]-Таблица1[[#This Row],[Z]]) -> 4.5090847 | E5: =ABS(Таблица1[[#This Row],[Остатки]]/Таблица1[[#This Row],[Z]]) -> 4.5090847 | F5: =Таблица1[[#This Row],[Нормированные остатки]]-E6 -> 2.7509838
A6: 30 | B6: -2 | C6: =$H$3+$H$2*A6 -> -5.5162019 | D6: =ABS(Таблица1[[#This Row],[Предсказанные значения]]-Таблица1[[#This Row],[Z]]) -> 3.5162019 | E6: =ABS(Таблица1[[#This Row],[Остатки]]/Таблица1[[#This Row],[Z]]) -> 1.7581009 | F6: =Таблица1[[#This Row],[Нормированные остатки]]-E7 -> 1.6774679
A7: 30 | B7: -6 | C7: =$H$3+$H$2*A7 -> -5.5162019 | D7: =ABS(Таблица1[[#This Row],[Предсказанные значения]]-Таблица1[[#This Row],[Z]]) -> 0.48379815 | E7: =ABS(Таблица1[[#This Row],[Остатки]]/Таблица1[[#This Row],[Z]]) -> 0.080633024 | F7: =Таблица1[[#This Row],[Нормированные остатки]]-E8 -> -0.00029654813
A8: 32 | B8: -6 | C8: =$H$3+$H$2*A8 -> -5.5144226 | D8: =ABS(Таблица1[[#This Row],[Предсказанные значения]]-Таблица1[[#This Row],[Z]]) -> 0.48557743 | E8: =ABS(Таблица1[[#This Row],[Остатки]]/Таблица1[[#This Row],[Z]]) -> 0.080929572 | F8: =Таблица1[[#This Row],[Нормированные остатки]]-E9 -> -0.020887367
A9: 38 | B9: -5 | C9: =$H$3+$H$2*A9 -> -5.5090847 | D9: =ABS(Таблица1[[#This Row],[Предсказанные значения]]-Таблица1[[#This Row],[Z]]) -> 0.5090847 | E9: =ABS(Таблица1[[#This Row],[Остатки]]/Таблица1[[#This Row],[Z]]) -> 0.10181694 | F9: =Таблица1[[#This Row],[Нормированные остатки]]-E10 -> -0.34691873
A10: 34 | B10: -10 | C10: =$H$3+$H$2*A10 -> -5.5126433 | D10: =ABS(Таблица1[[#This Row],[Предсказанные значения]]-Таблица1[[#This Row],[Z]]) -> 4.4873567 | E10: =ABS(Таблица1[[#This Row],[Остатки]]/Таблица1[[#This Row],[Z]]) -> 0.44873567 | F10: =Таблица1[[#This Row],[Нормированные остатки]]-E11 -> 0.070574853
A11: 34 | B11: -4 | C11: =$H$3+$H$2*A11 -> -5.5126433 | D11: =ABS(Таблица1[[#This Row],[Предсказанные значения]]-Таблица1[[#This Row],[Z]]) -> 1.5126433 | E11: =ABS(Таблица1[[#This Row],[Остатки]]/Таблица1[[#This Row],[Z]]) -> 0.37816082 | F11: =Таблица1[[#This Row],[Нормированные остатки]]-E12 -> -0.010015207
A12: 41 | B12: -9 | C12: =$H$3+$H$2*A12 -> -5.5064158 | D12: =ABS(Таблица1[[#This Row],[Предсказанные значения]]-Таблица1[[#This Row],[Z]]) -> 3.4935842 | E12: =ABS(Таблица1[[#This Row],[Остатки]]/Таблица1[[#This Row],[Z]]) -> 0.38817603 | F12: =Таблица1[[#This Row],[Нормированные остатки]]-E13 -> 0.28618116
A13: 37 | B13: -5 | C13: =$H$3+$H$2*A13 -> -5.5099743 | D13: =ABS(Таблица1[[#This Row],[Предсказанные значения]]-Таблица1[[#This Row],[Z]]) -> 0.50997434 | E13: =ABS(Таблица1[[#This Row],[Остатки]]/Таблица1[[#This Row],[Z]]) -> 0.10199487 | F13: =Таблица1[[#This Row],[Нормированные остатки]]-E14 -> -0.11112012
A14: 39 | B14: -7 | C14: =$H$3+$H$2*A14 -> -5.5081951 | D14: =ABS(Таблица1[[#This Row],[Предсказанные значения]]-Таблица1[[#This Row],[Z]]) -> 1.4918049 | E14: =ABS(Таблица1[[#This Row],[Остатки]]/Таблица1[[#This Row],[Z]]) -> 0.21311499 | F14: =Таблица1[[#This Row],[Нормированные остатки]]-E15 -> -0.62383967
A15: 36 | B15: -3 | C15: =$H$3+$H$2*A15 -> -5.510864 | D15: =ABS(Таблица1[[#This Row],[Предсказанные значения]]-Таблица1[[#This Row],[Z]]) -> 2.510864 | E15: =ABS(Таблица1[[#This Row],[Остатки]]/Таблица1[[#This Row],[Z]]) -> 0.83695466 | F15: =Таблица1[[#This Row],[Нормированные остатки]]-E16 -> 0.38821899
... A23: 34 | B23: -10 | C23: =$H$3+$H$2*A23 -> -5.5126433 | D23: =ABS(Таблица1[[#This Row],[Предсказанные значения]]-Таблица1[[#This Row],[Z]]) -> 4.4873567 | E23: =ABS(Таблица1[[#This Row],[Остатки]]/Таблица1[[#This Row],[Z]]) -> 0.44873567 | F23: =Таблица1[[#This Row],[Нормированные остатки]]-E24 -> -0.38732935
A24: 39 | B24: -3 | C24: =$H$3+$H$2*A24 -> -5.5081951 | D24: =ABS(Таблица1[[#This Row],[Предсказанные значения]]-Таблица1[[#This Row],[Z]]) -> 2.5081951 | E24: =ABS(Таблица1[[#This Row],[Остатки]]/Таблица1[[#This Row],[Z]]) -> 0.83606502 | F24: =Таблица1[[#This Row],[Нормированные остатки]]-E25 -> 0.4470982 | G24: Средняя ошибка аппроксимации | H24: =SUM(Таблица1[Нормированные остатки])/COUNT(Таблица1[X]) -> 0.92634229 | I24: Высокая средняя ошибка :(
A25: 49 | B25: -9 | C25: =$H$3+$H$2*A25 -> -5.4992986 | D25: =ABS(Таблица1[[#This Row],[Предсказанные значения]]-Таблица1[[#This Row],[Z]]) -> 3.5007014 | E25: =ABS(Таблица1[[#This Row],[Остатки]]/Таблица1[[#This Row],[Z]]) -> 0.38896682 | F25: =Таблица1[[#This Row],[Нормированные остатки]]-E26 -> 0.30951999 | G25: Средняя эластичность | H25: =H2*AVERAGE(Таблица1[X])/AVERAGE(Таблица1[Z]) -> -0.0057665457
A26: 22 | B26: -6 | C26: =$H$3+$H$2*A26 -> -5.523319 | D26: =ABS(Таблица1[[#This Row],[Предсказанные значения]]-Таблица1[[#This Row],[Z]]) -> 0.47668099 | E26: =ABS(Таблица1[[#This Row],[Остатки]]/Таблица1[[#This Row],[Z]]) -> 0.079446832 | F26: =Таблица1[[#This Row],[Нормированные остатки]]-E27 -> -1.6706473
A27: 48 | B27: -2 | C27: =$H$3+$H$2*A27 -> -5.5001883 | D27: =ABS(Таблица1[[#This Row],[Предсказанные значения]]-Таблица1[[#This Row],[Z]]) -> 3.5001883 | E27: =ABS(Таблица1[[#This Row],[Остатки]]/Таблица1[[#This Row],[Z]]) -> 1.7500941 | F27: =Таблица1[[#This Row],[Нормированные остатки]]-E28 -> -0.0080067994 | G27: Проверка условий Гаусса-Маркова | H27: Выводы, значения
A28: 30 | B28: -2 | C28: =$H$3+$H$2*A28 -> -5.5162019 | D28: =ABS(Таблица1[[#This Row],[Предсказанные значения]]-Таблица1[[#This Row],[Z]]) -> 3.5162019 | E28: =ABS(Таблица1[[#This Row],[Остатки]]/Таблица1[[#This Row],[Z]]) -> 1.7581009 | F28: =Таблица1[[#This Row],[Нормированные остатки]]-E29 -> 1.4477374 | G28: МE = 0 | H28: =AVERAGE(Таблица1[Остатки])/COUNT(Таблица1[X]) -> 0.028644721
A29: 29 | B29: -8 | C29: =$H$3+$H$2*A29 -> -5.5170915 | D29: =ABS(Таблица1[[#This Row],[Предсказанные значения]]-Таблица1[[#This Row],[Z]]) -> 2.4829085 | E29: =ABS(Таблица1[[#This Row],[Остатки]]/Таблица1[[#This Row],[Z]]) -> 0.31036356 | F29: =Таблица1[[#This Row],[Нормированные остатки]]-E30 -> -0.076626271 | G29: Dei = const | H29: На графике остатков не наблюдаем никаких "воронок", точки случайно распределены по полю
A30: 29 | B30: -9 | C30: =$H$3+$H$2*A30 -> -5.5170915 | D30: =ABS(Таблица1[[#This Row],[Предсказанные значения]]-Таблица1[[#This Row],[Z]]) -> 3.4829085 | E30: =ABS(Таблица1[[#This Row],[Остатки]]/Таблица1[[#This Row],[Z]]) -> 0.38698983 | F30: =Таблица1[[#This Row],[Нормированные остатки]]-E31 -> -1.3675525 | G30: Отсутствие автокорреляции (cov(ei,ej) = 0) | H30: =SUMSQ(Таблица1[Шаг остатка])/SUMSQ(Таблица1[Нормированные остатки]) -> 1.1890037 | I30: (Вообще, в условиях теста Дарбина-Уотсона требуется, чтобы ME=0 выполнялось)
A31: 38 | B31: -2 | C31: =$H$3+$H$2*A31 -> -5.5090847 | D31: =ABS(Таблица1[[#This Row],[Предсказанные значения]]-Таблица1[[#This Row],[Z]]) -> 3.5090847 | E31: =ABS(Таблица1[[#This Row],[Остатки]]/Таблица1[[#This Row],[Z]]) -> 1.7545423 | F31: =Таблица1[[#This Row],[Нормированные остатки]]-E32 -> 1.4432891 | G31: Не выполнены 1 и 3 условия!
A32: 37 | B32: -8 | C32: =$H$3+$H$2*A32 -> -5.5099743 | D32: =ABS(Таблица1[[#This Row],[Предсказанные значения]]-Таблица1[[#This Row],[Z]]) -> 2.4900257 | E32: =ABS(Таблица1[[#This Row],[Остатки]]/Таблица1[[#This Row],[Z]]) -> 0.31125321 | F32: =Таблица1[[#This Row],[Нормированные остатки]]-E33 -> -0.07830671 | G32: Также видим, что модель явно имеет не линейную зависимость, модель данных и их устройство явно отличны друг от друга
A33: 55 | B33: -9 | C33: =$H$3+$H$2*A33 -> -5.4939607 | D33: =ABS(Таблица1[[#This Row],[Предсказанные значения]]-Таблица1[[#This Row],[Z]]) -> 3.5060393 | E33: =ABS(Таблица1[[#This Row],[Остатки]]/Таблица1[[#This Row],[Z]]) -> 0.38955992 | F33: =Таблица1[[#This Row],[Нормированные остатки]]-E34 -> 0.17657202 | G33: В общем, всё плохо
A34: 38 | B34: -7 | C34: =$H$3+$H$2*A34 -> -5.5090847 | D34: =ABS(Таблица1[[#This Row],[Предсказанные значения]]-Таблица1[[#This Row],[Z]]) -> 1.4909153 | E34: =ABS(Таблица1[[#This Row],[Остатки]]/Таблица1[[#This Row],[Z]]) -> 0.2129879 | F34: =Таблица1[[#This Row],[Нормированные остатки]]-E35 -> -1.5464475
A35: 27 | B35: -2 | C35: =$H$3+$H$2*A35 -> -5.5188708 | D35: =ABS(Таблица1[[#This Row],[Предсказанные значения]]-Таблица1[[#This Row],[Z]]) -> 3.5188708 | E35: =ABS(Таблица1[[#This Row],[Остатки]]/Таблица1[[#This Row],[Z]]) -> 1.7594354 | F35: =Таблица1[[#This Row],[Нормированные остатки]]-E36 -> 1.658686 | G35: Коэффициент корреляции rxz | H35: =_xlfn.COVARIANCE.S(Xval, Zval)/SQRT(_xlfn.VAR.S(Xval)*_xlfn.VAR.S(Zval)) -> 0.0025542176
A36: 44 | B36: -5 | C36: =$H$3+$H$2*A36 -> -5.5037468 | D36: =ABS(Таблица1[[#This Row],[Предсказанные значения]]-Таблица1[[#This Row],[Z]]) -> 0.50374683 | E36: =ABS(Таблица1[[#This Row],[Остатки]]/Таблица1[[#This Row],[Z]]) -> 0.10074937 | F36: =Таблица1[[#This Row],[Нормированные остатки]]-E37 -> -0.73264672 | G36: Коэффициент детерминации R² | H36: =1-SUMSQ(Таблица1[Остатки])/DEVSQ(Zval) -> 6.5240277e-06
A37: 48 | B37: -3 | C37: =$H$3+$H$2*A37 -> -5.5001883 | D37: =ABS(Таблица1[[#This Row],[Предсказанные значения]]-Таблица1[[#This Row],[Z]]) -> 2.5001883 | E37: =ABS(Таблица1[[#This Row],[Остатки]]/Таблица1[[#This Row],[Z]]) -> 0.83339609 | F37: =Таблица1[[#This Row],[Нормированные остатки]]-E38 -> 0.75202169 | G37: Так как коэффициенты уж слишком низкие, можем говорить лишь о малой связи X и Z, а также о плохой линеаризуемости данных
A38: 35 | B38: -6 | C38: =$H$3+$H$2*A38 -> -5.5117536 | D38: =ABS(Таблица1[[#This Row],[Предсказанные значения]]-Таблица1[[#This Row],[Z]]) -> 0.48824637 | E38: =ABS(Таблица1[[#This Row],[Остатки]]/Таблица1[[#This Row],[Z]]) -> 0.081374395 | F38: =Таблица1[[#This Row],[Нормированные остатки]]-E39 -> -0.36745024
A39: 35 | B39: -10 | C39: =$H$3+$H$2*A39 -> -5.5117536 | D39: =ABS(Таблица1[[#This Row],[Предсказанные значения]]-Таблица1[[#This Row],[Z]]) -> 4.4882464 | E39: =ABS(Таблица1[[#This Row],[Остатки]]/Таблица1[[#This Row],[Z]]) -> 0.44882464 | F39: =Таблица1[[#This Row],[Нормированные остатки]]-E40 -> 0.069329351 | G39: F-тест | H39: Значения
A40: 28 | B40: -4 | C40: =$H$3+$H$2*A40 -> -5.5179811 | D40: =ABS(Таблица1[[#This Row],[Предсказанные значения]]-Таблица1[[#This Row],[Z]]) -> 1.5179811 | E40: =ABS(Таблица1[[#This Row],[Остатки]]/Таблица1[[#This Row],[Z]]) -> 0.37949529 | F40: =Таблица1[[#This Row],[Нормированные остатки]]-E41 -> 0.16638029 | G40: F-статистика | H40: =help_linear_xz!E12 -> 0.00057411819
A41: 39 | B41: -7 | C41: =$H$3+$H$2*A41 -> -5.5081951 | D41: =ABS(Таблица1[[#This Row],[Предсказанные значения]]-Таблица1[[#This Row],[Z]]) -> 1.4918049 | E41: =ABS(Таблица1[[#This Row],[Остатки]]/Таблица1[[#This Row],[Z]]) -> 0.21311499 | F41: =Таблица1[[#This Row],[Нормированные остатки]]-E42 -> -1.5414274 | G41: F-критическое | H41: =FINV(0.05,help_linear_xz!B12,help_linear_xz!B13) -> 3.949321
A42: 38 | B42: -2 | C42: =$H$3+$H$2*A42 -> -5.5090847 | D42: =ABS(Таблица1[[#This Row],[Предсказанные значения]]-Таблица1[[#This Row],[Z]]) -> 3.5090847 | E42: =ABS(Таблица1[[#This Row],[Остатки]]/Таблица1[[#This Row],[Z]]) -> 1.7545423 | F42: =Таблица1[[#This Row],[Нормированные остатки]]-E43 -> 1.3766039 | G42: Отвергаем гипотезу об описании данных линейной зависимостью (alpha = 0.05, F-статистика < F-критическое)
A43: 35 | B43: -4 | C43: =$H$3+$H$2*A43 -> -5.5117536 | D43: =ABS(Таблица1[[#This Row],[Предсказанные значения]]-Таблица1[[#This Row],[Z]]) -> 1.5117536 | E43: =ABS(Таблица1[[#This Row],[Остатки]]/Таблица1[[#This Row],[Z]]) -> 0.37793841 | F43: =Таблица1[[#This Row],[Нормированные остатки]]-E44 -> -0.071331051
A44: 40 | B44: -10 | C44: =$H$3+$H$2*A44 -> -5.5073054 | D44: =ABS(Таблица1[[#This Row],[Предсказанные значения]]-Таблица1[[#This Row],[Z]]) -> 4.4926946 | E44: =ABS(Таблица1[[#This Row],[Остатки]]/Таблица1[[#This Row],[Z]]) -> 0.44926946 | F44: =Таблица1[[#This Row],[Нормированные остатки]]-E45 -> -0.00035585775 | G44: t-тест (на качество коэффициента a) | H44: Значения
A45: 44 | B45: -10 | C45: =$H$3+$H$2*A45 -> -5.5037468 | D45: =ABS(Таблица1[[#This Row],[Предсказанные значения]]-Таблица1[[#This Row],[Z]]) -> 4.4962532 | E45: =ABS(Таблица1[[#This Row],[Остатки]]/Таблица1[[#This Row],[Z]]) -> 0.44962532 | F45: =Таблица1[[#This Row],[Нормированные остатки]]-E46 -> 0.062536634 | G45: t-статистика | H45: =help_linear_xz!D18 -> 0.023960763
A46: 30 | B46: -9 | C46: =$H$3+$H$2*A46 -> -5.5162019 | D46: =ABS(Таблица1[[#This Row],[Предсказанные значения]]-Таблица1[[#This Row],[Z]]) -> 3.4837981 | E46: =ABS(Таблица1[[#This Row],[Остатки]]/Таблица1[[#This Row],[Z]]) -> 0.38708868 | F46: =Таблица1[[#This Row],[Нормированные остатки]]-E47 -> -0.062447669 | G46: t-критическое | H46: {=_xlfn.T.INV(0.95,COUNT(Таблица1[X]-2))} -> 1.6619611
A47: 43 | B47: -10 | C47: =$H$3+$H$2*A47 -> -5.5046365 | D47: =ABS(Таблица1[[#This Row],[Предсказанные значения]]-Таблица1[[#This Row],[Z]]) -> 4.4953635 | E47: =ABS(Таблица1[[#This Row],[Остатки]]/Таблица1[[#This Row],[Z]]) -> 0.44953635 | F47: =Таблица1[[#This Row],[Нормированные остатки]]-E48 -> 0 | G47: Принимаем гипотезу о равенстве a = 0 (alpha = 0.05, t-статистика < t-критическое)
...

Sheet help_linear_xz
A1: ВЫВОД ИТОГОВ
A3: Регрессионная статистика
A4: Множественный R | B4: 0.0025542176
A5: R-квадрат | B5: 6.5240277e-06
A6: Нормированный R-квадрат | B6: -0.011357038
A7: Стандартная ошибка | B7: 3.1051339
A8: Наблюдения | B8: 90
A10: Дисперсионный анализ
B11: df | C11: SS | D11: MS | E11: F | F11: Значимость F
A12: Регрессия | B12: 1 | C12: 0.005535565 | D12: 0.005535565 | E12: 0.00057411819 | F12: 0.98093816
A13: Остаток | B13: 88 | C13: 848.48335 | D13: 9.6418563
A14: Итого | B14: 89 | C14: 848.48889
B16: Коэффициенты | C16: Стандартная ошибка | D16: t-статистика | E16: P-Значение | F16: Нижние 95% | G16: Верхние 95% | H16: Нижние 95.0% | I16: Верхние 95.0%
A17: Y-пересечение | B17: -5.5428912 | C17: 1.3661276 | D17: -4.0573745 | E17: 0.00010712537 | F17: -8.2577827 | G17: -2.8279997 | H17: -8.2577827 | I17: -2.8279997
A18: X | B18: 0.00088964438 | C18: 0.037129217 | D18: 0.023960763 | E18: 0.98093816 | F18: -0.072896872 | G18: 0.074676161 | H18: -0.072896872 | I18: 0.074676161
A22: ВЫВОД ОСТАТКА
A24: Наблюдение | B24: Предсказанное Z | C24: Остатки | D24: Стандартные остатки
A25: 1 | B25: -5.5206501 | C25: -1.4793499 | D25: -0.47911995
A26: 2 | B26: -5.5010779 | C26: -0.4989221 | D26: -0.16158688
A27: 3 | B27: -5.5055261 | C27: -4.4944739 | D27: -1.455634
A28: 4 | B28: -5.5090847 | C28: 4.5090847 | D28: 1.4603661
A29: 5 | B29: -5.5162019 | C29: 3.5162019 | D29: 1.1387992
A30: 6 | B30: -5.5162019 | C30: -0.48379815 | D30: -0.15668865
A31: 7 | B31: -5.5144226 | C31: -0.48557743 | D31: -0.15726491
A32: 8 | B32: -5.5090847 | C32: 0.5090847 | D32: 0.16487826
A33: 9 | B33: -5.5126433 | C33: -4.4873567 | D33: -1.453329
A34: 10 | B34: -5.5126433 | C34: 1.5126433 | D34: 0.48990273
A35: 11 | B35: -5.5064158 | C35: -3.4935842 | D35: -1.1314739
A36: 12 | B36: -5.5099743 | C36: 0.50997434 | D36: 0.16516639
... A114: 90 | B114: -5.5117536 | C114: -4.4882464 | D114: -1.4536171

Sheet hyperbolic_xz
A1: X | B1: 1/X | C1: Z | D1: Предсказанные значения | E1: Остатки | F1: Нормированные остатки | G1: Коэффициенты | H1: Значения
A2: 25 | B2: =1/A2 -> 0.04 | C2: -7 | D2: =$H$2*Таблица2[[#This Row],[1/X]]+$H$3 -> -5.2807437 | E2: =ABS(Таблица2[[#This Row],[Предсказанные значения]]-Таблица2[[#This Row],[Z]]) -> 1.7192563 | F2: =ABS(Таблица2[[#This Row],[Остатки]]/Таблица2[[#This Row],[Z]]) -> 0.24560805 | G2: a | H2: 23.217173
A3: 47 | B3: =1/A3 -> 0.021276596 | C3: -6 | D3: =$H$2*Таблица2[[#This Row],[1/X]]+$H$3 -> -5.7154482 | E3: =ABS(Таблица2[[#This Row],[Предсказанные значения]]-Таблица2[[#This Row],[Z]]) -> 0.2845518 | F3: =ABS(Таблица2[[#This Row],[Остатки]]/Таблица2[[#This Row],[Z]]) -> 0.0474253 | G3: b | H3: -6.2094306
A4: 42 | B4: =1/A4 -> 0.023809524 | C4: -10 | D4: =$H$2*Таблица2[[#This Row],[1/X]]+$H$3 -> -5.6566408 | E4: =ABS(Таблица2[[#This Row],[Предсказанные значения]]-Таблица2[[#This Row],[Z]]) -> 4.3433592 | F4: =ABS(Таблица2[[#This Row],[Остатки]]/Таблица2[[#This Row],[Z]]) -> 0.43433592 | G4: Средняя ошибка аппроксимации | H4: =SUM(Таблица2[Нормированные остатки])/COUNT(Таблица2[X]) -> 0.9273634 | I4: Ошибка даже выше, чем при линейной модели!
A5: 38 | B5: =1/A5 -> 0.026315789 | C5: -1 | D5: =$H$2*Таблица2[[#This Row],[1/X]]+$H$3 -> -5.5984524 | E5: =ABS(Таблица2[[#This Row],[Предсказанные значения]]-Таблица2[[#This Row],[Z]]) -> 4.5984524 | F5: =ABS(Таблица2[[#This Row],[Остатки]]/Таблица2[[#This Row],[Z]]) -> 4.5984524
A6: 30 | B6: =1/A6 -> 0.033333333 | C6: -2 | D6: =$H$2*Таблица2[[#This Row],[1/X]]+$H$3 -> -5.4355248 | E6: =ABS(Таблица2[[#This Row],[Предсказанные значения]]-Таблица2[[#This Row],[Z]]) -> 3.4355248 | F6: =ABS(Таблица2[[#This Row],[Остатки]]/Таблица2[[#This Row],[Z]]) -> 1.7177624
A7: 30 | B7: =1/A7 -> 0.033333333 | C7: -6 | D7: =$H$2*Таблица2[[#This Row],[1/X]]+$H$3 -> -5.4355248 | E7: =ABS(Таблица2[[#This Row],[Предсказанные значения]]-Таблица2[[#This Row],[Z]]) -> 0.56447517 | F7: =ABS(Таблица2[[#This Row],[Остатки]]/Таблица2[[#This Row],[Z]]) -> 0.094079195
A8: 32 | B8: =1/A8 -> 0.03125 | C8: -6 | D8: =$H$2*Таблица2[[#This Row],[1/X]]+$H$3 -> -5.4838939 | E8: =ABS(Таблица2[[#This Row],[Предсказанные значения]]-Таблица2[[#This Row],[Z]]) -> 0.51610606 | F8: =ABS(Таблица2[[#This Row],[Остатки]]/Таблица2[[#This Row],[Z]]) -> 0.086017677
A9: 38 | B9: =1/A9 -> 0.026315789 | C9: -5 | D9: =$H$2*Таблица2[[#This Row],[1/X]]+$H$3 -> -5.5984524 | E9: =ABS(Таблица2[[#This Row],[Предсказанные значения]]-Таблица2[[#This Row],[Z]]) -> 0.59845236 | F9: =ABS(Таблица2[[#This Row],[Остатки]]/Таблица2[[#This Row],[Z]]) -> 0.11969047
A10: 34 | B10: =1/A10 -> 0.029411765 | C10: -10 | D10: =$H$2*Таблица2[[#This Row],[1/X]]+$H$3 -> -5.5265726 | E10: =ABS(Таблица2[[#This Row],[Предсказанные значения]]-Таблица2[[#This Row],[Z]]) -> 4.4734274 | F10: =ABS(Таблица2[[#This Row],[Остатки]]/Таблица2[[#This Row],[Z]]) -> 0.44734274
A11: 34 | B11: =1/A11 -> 0.029411765 | C11: -4 | D11: =$H$2*Таблица2[[#This Row],[1/X]]+$H$3 -> -5.5265726 | E11: =ABS(Таблица2[[#This Row],[Предсказанные значения]]-Таблица2[[#This Row],[Z]]) -> 1.5265726 | F11: =ABS(Таблица2[[#This Row],[Остатки]]/Таблица2[[#This Row],[Z]]) -> 0.38164314
A12: 41 | B12: =1/A12 -> 0.024390244 | C12: -9 | D12: =$H$2*Таблица2[[#This Row],[1/X]]+$H$3 -> -5.6431581 | E12: =ABS(Таблица2[[#This Row],[Предсказанные значения]]-Таблица2[[#This Row],[Z]]) -> 3.3568419 | F12: =ABS(Таблица2[[#This Row],[Остатки]]/Таблица2[[#This Row],[Z]]) -> 0.37298243
A13: 37 | B13: =1/A13 -> 0.027027027 | C13: -5 | D13: =$H$2*Таблица2[[#This Row],[1/X]]+$H$3 -> -5.5819394 | E13: =ABS(Таблица2[[#This Row],[Предсказанные значения]]-Таблица2[[#This Row],[Z]]) -> 0.58193944 | F13: =ABS(Таблица2[[#This Row],[Остатки]]/Таблица2[[#This Row],[Z]]) -> 0.11638789
A14: 39 | B14: =1/A14 -> 0.025641026 | C14: -7 | D14: =$H$2*Таблица2[[#This Row],[1/X]]+$H$3 -> -5.6141185 | E14: =ABS(Таблица2[[#This Row],[Предсказанные значения]]-Таблица2[[#This Row],[Z]]) -> 1.3858815 | F14: =ABS(Таблица2[[#This Row],[Остатки]]/Таблица2[[#This Row],[Z]]) -> 0.19798308
A15: 36 | B15: =1/A15 -> 0.027777778 | C15: -3 | D15: =$H$2*Таблица2[[#This Row],[1/X]]+$H$3 -> -5.5645091 | E15: =ABS(Таблица2[[#This Row],[Предсказанные значения]]-Таблица2[[#This Row],[Z]]) -> 2.5645091 | F15: =ABS(Таблица2[[#This Row],[Остатки]]/Таблица2[[#This Row],[Z]]) -> 0.85483638
A16: 34 | B16: =1/A16 -> 0.029411765 | C16: -10 | D16: =$H$2*Таблица2[[#This Row],[1/X]]+$H$3 -> -5.5265726 | E16: =ABS(Таблица2[[#This Row],[Предсказанные значения]]-Таблица2[[#This Row],[Z]]) -> 4.4734274 | F16: =ABS(Таблица2[[#This Row],[Остатки]]/Таблица2[[#This Row],[Z]]) -> 0.44734274
... A25: 49 | B25: =1/A25 -> 0.020408163 | C25: -9 | D25: =$H$2*Таблица2[[#This Row],[1/X]]+$H$3 -> -5.7356107 | E25: =ABS(Таблица2[[#This Row],[Предсказанные значения]]-Таблица2[[#This Row],[Z]]) -> 3.2643893 | F25: =ABS(Таблица2[[#This Row],[Остатки]]/Таблица2[[#This Row],[Z]]) -> 0.36270992
A26: 22 | B26: =1/A26 -> 0.045454545 | C26: -6 | D26: =$H$2*Таблица2[[#This Row],[1/X]]+$H$3 -> -5.1541045 | E26: =ABS(Таблица2[[#This Row],[Предсказанные значения]]-Таблица2[[#This Row],[Z]]) -> 0.84589545 | F26: =ABS(Таблица2[[#This Row],[Остатки]]/Таблица2[[#This Row],[Z]]) -> 0.14098258 | G26: Коэффициент корреляции rxz | H26: =_xlfn.COVARIANCE.S(Таблица2[1/X], Таблица2[Z])/SQRT(_xlfn.VAR.S(Таблица2[1/X])*_xlfn.VAR.S(Таблица2[Z])) -> 0.0690371
A27: 48 | B27: =1/A27 -> 0.020833333 | C27: -2 | D27: =$H$2*Таблица2[[#This Row],[1/X]]+$H$3 -> -5.7257395 | E27: =ABS(Таблица2[[#This Row],[Предсказанные значения]]-Таблица2[[#This Row],[Z]]) -> 3.7257395 | F27: =ABS(Таблица2[[#This Row],[Остатки]]/Таблица2[[#This Row],[Z]]) -> 1.8628697 | G27: Коэффициент детерминации R² | H27: =1-SUMSQ(Таблица2[Остатки])/DEVSQ(Таблица2[Z]) -> 0.0047661212
A28: 30 | B28: =1/A28 -> 0.033333333 | C28: -2 | D28: =$H$2*Таблица2[[#This Row],[1/X]]+$H$3 -> -5.4355248 | E28: =ABS(Таблица2[[#This Row],[Предсказанные значения]]-Таблица2[[#This Row],[Z]]) -> 3.4355248 | F28: =ABS(Таблица2[[#This Row],[Остатки]]/Таблица2[[#This Row],[Z]]) -> 1.7177624 | G28: Коэффициенты низкие, малая корреляционная зависимость
A29: 29 | B29: =1/A29 -> 0.034482759 | C29: -8 | D29: =$H$2*Таблица2[[#This Row],[1/X]]+$H$3 -> -5.4088384 | E29: =ABS(Таблица2[[#This Row],[Предсказанные значения]]-Таблица2[[#This Row],[Z]]) -> 2.5911616 | F29: =ABS(Таблица2[[#This Row],[Остатки]]/Таблица2[[#This Row],[Z]]) -> 0.3238952
A30: 29 | B30: =1/A30 -> 0.034482759 | C30: -9 | D30: =$H$2*Таблица2[[#This Row],[1/X]]+$H$3 -> -5.4088384 | E30: =ABS(Таблица2[[#This Row],[Предсказанные значения]]-Таблица2[[#This Row],[Z]]) -> 3.5911616 | F30: =ABS(Таблица2[[#This Row],[Остатки]]/Таблица2[[#This Row],[Z]]) -> 0.39901795 | G30: F-тест | H30: Значения
A31: 38 | B31: =1/A31 -> 0.026315789 | C31: -2 | D31: =$H$2*Таблица2[[#This Row],[1/X]]+$H$3 -> -5.5984524 | E31: =ABS(Таблица2[[#This Row],[Предсказанные значения]]-Таблица2[[#This Row],[Z]]) -> 3.5984524 | F31: =ABS(Таблица2[[#This Row],[Остатки]]/Таблица2[[#This Row],[Z]]) -> 1.7992262 | G31: F-статистика | H31: =help_hyperbolic_xz!E12 -> 0.42142724
A32: 37 | B32: =1/A32 -> 0.027027027 | C32: -8 | D32: =$H$2*Таблица2[[#This Row],[1/X]]+$H$3 -> -5.5819394 | E32: =ABS(Таблица2[[#This Row],[Предсказанные значения]]-Таблица2[[#This Row],[Z]]) -> 2.4180606 | F32: =ABS(Таблица2[[#This Row],[Остатки]]/Таблица2[[#This Row],[Z]]) -> 0.30225757 | G32: F-критическое | H32: =FINV(0.05,help_hyperbolic_xz!B12,help_hyperbolic_xz!B13) -> 3.949321
A33: 55 | B33: =1/A33 -> 0.018181818 | C33: -9 | D33: =$H$2*Таблица2[[#This Row],[1/X]]+$H$3 -> -5.7873002 | E33: =ABS(Таблица2[[#This Row],[Предсказанные значения]]-Таблица2[[#This Row],[Z]]) -> 3.2126998 | F33: =ABS(Таблица2[[#This Row],[Остатки]]/Таблица2[[#This Row],[Z]]) -> 0.35696665 | G33: Отвергаем гипотезу об описании данных гиперболической зависимостью (alpha = 0.05)
A34: 38 | B34: =1/A34 -> 0.026315789 | C34: -7 | D34: =$H$2*Таблица2[[#This Row],[1/X]]+$H$3 -> -5.5984524 | E34: =ABS(Таблица2[[#This Row],[Предсказанные значения]]-Таблица2[[#This Row],[Z]]) -> 1.4015476 | F34: =ABS(Таблица2[[#This Row],[Остатки]]/Таблица2[[#This Row],[Z]]) -> 0.20022109
A35: 27 | B35: =1/A35 -> 0.037037037 | C35: -2 | D35: =$H$2*Таблица2[[#This Row],[1/X]]+$H$3 -> -5.3495353 | E35: =ABS(Таблица2[[#This Row],[Предсказанные значения]]-Таблица2[[#This Row],[Z]]) -> 3.3495353 | F35: =ABS(Таблица2[[#This Row],[Остатки]]/Таблица2[[#This Row],[Z]]) -> 1.6747676 | G35: t-тест (на качество коэффициента a) | H35: Значения
A36: 44 | B36: =1/A36 -> 0.022727273 | C36: -5 | D36: =$H$2*Таблица2[[#This Row],[1/X]]+$H$3 -> -5.6817676 | E36: =ABS(Таблица2[[#This Row],[Предсказанные значения]]-Таблица2[[#This Row],[Z]]) -> 0.68176758 | F36: =ABS(Таблица2[[#This Row],[Остатки]]/Таблица2[[#This Row],[Z]]) -> 0.13635352 | G36: t-статистика | H36: =help_hyperbolic_xz!D18 -> 0.64917427
A37: 48 | B37: =1/A37 -> 0.020833333 | C37: -3 | D37: =$H$2*Таблица2[[#This Row],[1/X]]+$H$3 -> -5.7257395 | E37: =ABS(Таблица2[[#This Row],[Предсказанные значения]]-Таблица2[[#This Row],[Z]]) -> 2.7257395 | F37: =ABS(Таблица2[[#This Row],[Остатки]]/Таблица2[[#This Row],[Z]]) -> 0.90857983 | G37: t-критическое | H37: {=_xlfn.T.INV(0.95,COUNT(Таблица2[1/X]-2))} -> 1.6619611
A38: 35 | B38: =1/A38 -> 0.028571429 | C38: -6 | D38: =$H$2*Таблица2[[#This Row],[1/X]]+$H$3 -> -5.5460828 | E38: =ABS(Таблица2[[#This Row],[Предсказанные значения]]-Таблица2[[#This Row],[Z]]) -> 0.4539172 | F38: =ABS(Таблица2[[#This Row],[Остатки]]/Таблица2[[#This Row],[Z]]) -> 0.075652867 | G38: Принимаем гипотезу о равенстве a = 0 (alpha = 0.05)
A39: 35 | B39: =1/A39 -> 0.028571429 | C39: -10 | D39: =$H$2*Таблица2[[#This Row],[1/X]]+$H$3 -> -5.5460828 | E39: =ABS(Таблица2[[#This Row],[Предсказанные значения]]-Таблица2[[#This Row],[Z]]) -> 4.4539172 | F39: =ABS(Таблица2[[#This Row],[Остатки]]/Таблица2[[#This Row],[Z]]) -> 0.44539172
A40: 28 | B40: =1/A40 -> 0.035714286 | C40: -4 | D40: =$H$2*Таблица2[[#This Row],[1/X]]+$H$3 -> -5.3802458 | E40: =ABS(Таблица2[[#This Row],[Предсказанные значения]]-Таблица2[[#This Row],[Z]]) -> 1.3802458 | F40: =ABS(Таблица2[[#This Row],[Остатки]]/Таблица2[[#This Row],[Z]]) -> 0.34506146
A41: 39 | B41: =1/A41 -> 0.025641026 | C41: -7 | D41: =$H$2*Таблица2[[#This Row],[1/X]]+$H$3 -> -5.6141185 | E41: =ABS(Таблица2[[#This Row],[Предсказанные значения]]-Таблица2[[#This Row],[Z]]) -> 1.3858815 | F41: =ABS(Таблица2[[#This Row],[Остатки]]/Таблица2[[#This Row],[Z]]) -> 0.19798308
A42: 38 | B42: =1/A42 -> 0.026315789 | C42: -2 | D42: =$H$2*Таблица2[[#This Row],[1/X]]+$H$3 -> -5.5984524 | E42: =ABS(Таблица2[[#This Row],[Предсказанные значения]]-Таблица2[[#This Row],[Z]]) -> 3.5984524 | F42: =ABS(Таблица2[[#This Row],[Остатки]]/Таблица2[[#This Row],[Z]]) -> 1.7992262
A43: 35 | B43: =1/A43 -> 0.028571429 | C43: -4 | D43: =$H$2*Таблица2[[#This Row],[1/X]]+$H$3 -> -5.5460828 | E43: =ABS(Таблица2[[#This Row],[Предсказанные значения]]-Таблица2[[#This Row],[Z]]) -> 1.5460828 | F43: =ABS(Таблица2[[#This Row],[Остатки]]/Таблица2[[#This Row],[Z]]) -> 0.3865207
A44: 40 | B44: =1/A44 -> 0.025 | C44: -10 | D44: =$H$2*Таблица2[[#This Row],[1/X]]+$H$3 -> -5.6290013 | E44: =ABS(Таблица2[[#This Row],[Предсказанные значения]]-Таблица2[[#This Row],[Z]]) -> 4.3709987 | F44: =ABS(Таблица2[[#This Row],[Остатки]]/Таблица2[[#This Row],[Z]]) -> 0.43709987
A45: 44 | B45: =1/A45 -> 0.022727273 | C45: -10 | D45: =$H$2*Таблица2[[#This Row],[1/X]]+$H$3 -> -5.6817676 | E45: =ABS(Таблица2[[#This Row],[Предсказанные значения]]-Таблица2[[#This Row],[Z]]) -> 4.3182324 | F45: =ABS(Таблица2[[#This Row],[Остатки]]/Таблица2[[#This Row],[Z]]) -> 0.43182324
A46: 30 | B46: =1/A46 -> 0.033333333 | C46: -9 | D46: =$H$2*Таблица2[[#This Row],[1/X]]+$H$3 -> -5.4355248 | E46: =ABS(Таблица2[[#This Row],[Предсказанные значения]]-Таблица2[[#This Row],[Z]]) -> 3.5644752 | F46: =ABS(Таблица2[[#This Row],[Остатки]]/Таблица2[[#This Row],[Z]]) -> 0.3960528
A47: 43 | B47: =1/A47 -> 0.023255814 | C47: -10 | D47: =$H$2*Таблица2[[#This Row],[1/X]]+$H$3 -> -5.6694963 | E47: =ABS(Таблица2[[#This Row],[Предсказанные значения]]-Таблица2[[#This Row],[Z]]) -> 4.3305037 | F47: =ABS(Таблица2[[#This Row],[Остатки]]/Таблица2[[#This Row],[Z]]) -> 0.43305037
A48: 43 | B48: =1/A48 -> 0.023255814 | C48: -10 | D48: =$H$2*Таблица2[[#This Row],[1/X]]+$H$3 -> -5.6694963 | E48: =ABS(Таблица2[[#This Row],[Предсказанные значения]]-Таблица2[[#This Row],[Z]]) -> 4.3305037 | F48: =ABS(Таблица2[[#This Row],[Остатки]]/Таблица2[[#This Row],[Z]]) -> 0.43305037
...

Sheet help_hyperbolic_xz
A1: ВЫВОД ИТОГОВ
A3: Регрессионная статистика
A4: Множественный R | B4: 0.0690371
A5: R-квадрат | B5: 0.0047661212
A6: Нормированный R-квадрат | B6: -0.0065433547
A7: Стандартная ошибка | B7: 3.0977354
A8: Наблюдения | B8: 90
A10: Дисперсионный анализ
B11: df | C11: SS | D11: MS | E11: F | F11: Значимость F
A12: Регрессия | B12: 1 | C12: 4.0440009 | D12: 4.0440009 | E12: 0.42142724 | F12: 0.51791648
A13: Остаток | B13: 88 | C13: 844.44489 | D13: 9.5959646
A14: Итого | B14: 89 | C14: 848.48889
B16: Коэффициенты | C16: Стандартная ошибка | D16: t-статистика | E16: P-Значение | F16: Нижние 95% | G16: Верхние 95% | H16: Нижние 95.0% | I16: Верхние 95.0%
A17: Y-пересечение | B17: -6.2094306 | C17: 1.1241714 | D17: -5.5235621 | E17: 3.3282394e-07 | F17: -8.4434851 | G17: -3.9753761 | H17: -8.4434851 | I17: -3.9753761
A18: 1/X | B18: 23.217173 | C18: 35.764161 | D18: 0.64917427 | E18: 0.51791648 | F18: -47.856582 | G18: 94.290929 | H18: -47.856582 | I18: 94.290929
A22: ВЫВОД ОСТАТКА
A24: Наблюдение | B24: Предсказанное Z | C24: Остатки | D24: Стандартные остатки
A25: 1 | B25: -5.2807437 | C25: -1.7192563 | D25: -0.55814878
A26: 2 | B26: -5.7154482 | C26: -0.2845518 | D26: -0.092378454
A27: 3 | B27: -5.6566408 | C27: -4.3433592 | D27: -1.4100519
A28: 4 | B28: -5.5984524 | C28: 4.5984524 | D28: 1.4928667
A29: 5 | B29: -5.4355248 | C29: 3.4355248 | D29: 1.1153276
A30: 6 | B30: -5.4355248 | C30: -0.56447517 | D30: -0.18325431
A31: 7 | B31: -5.4838939 | C31: -0.51610606 | D31: -0.16755149
A32: 8 | B32: -5.5984524 | C32: 0.59845236 | D32: 0.19428485
A33: 9 | B33: -5.5265726 | C33: -4.4734274 | D33: -1.452278
A34: 10 | B34: -5.5265726 | C34: 1.5265726 | D34: 0.49559487
A35: 11 | B35: -5.6431581 | C35: -3.3568419 | D35: -1.0897835
A36: 12 | B36: -5.5819394 | C36: 0.58193944 | D36: 0.188924
... A114: 90 | B114: -5.5460828 | C114: -4.4539172 | D114: -1.445944

Sheet logarithmic_xz
A1: X | B1: ln(X) | C1: Z | D1: Предсказанные значения | E1: Остатки | F1: Нормированные остатки | G1: Коэффициенты | H1: Значения
A2: 25 | B2: =LN(A2) -> 3.2188758 | C2: -7 | D2: =B2*$H$2+$H$3 -> -5.3858728 | E2: =ABS(D2-C2) -> 1.6141272 | F2: =ABS(E2/C2) -> 0.2305896 | G2: a | H2: -0.38721751
A3: 47 | B3: =LN(A3) -> 3.8501476 | C3: -6 | D3: =B3*$H$2+$H$3 -> -5.6303123 | E3: =ABS(D3-C3) -> 0.36968771 | F3: =ABS(E3/C3) -> 0.061614619 | G3: b | H3: -4.1394677
A4: 42 | B4: =LN(A4) -> 3.7376696 | C4: -10 | D4: =B4*$H$2+$H$3 -> -5.5867588 | E4: =ABS(D4-C4) -> 4.4132412 | F4: =ABS(E4/C4) -> 0.44132412 | G4: Средняя ошибка аппроксимации | H4: =SUM(Таблица5[Нормированные остатки])/COUNT(Таблица5[X]) -> 0.92767294
A5: 38 | B5: =LN(A5) -> 3.6375862 | C5: -1 | D5: =B5*$H$2+$H$3 -> -5.5480048 | E5: =ABS(D5-C5) -> 4.5480048 | F5: =ABS(E5/C5) -> 4.5480048
A6: 30 | B6: =LN(A6) -> 3.4011974 | C6: -2 | D6: =B6*$H$2+$H$3 -> -5.4564709 | E6: =ABS(D6-C6) -> 3.4564709 | F6: =ABS(E6/C6) -> 1.7282354
A7: 30 | B7: =LN(A7) -> 3.4011974 | C7: -6 | D7: =B7*$H$2+$H$3 -> -5.4564709 | E7: =ABS(D7-C7) -> 0.5435291 | F7: =ABS(E7/C7) -> 0.090588183
A8: 32 | B8: =LN(A8) -> 3.4657359 | C8: -6 | D8: =B8*$H$2+$H$3 -> -5.4814613 | E8: =ABS(D8-C8) -> 0.51853866 | F8: =ABS(E8/C8) -> 0.086423109
A9: 38 | B9: =LN(A9) -> 3.6375862 | C9: -5 | D9: =B9*$H$2+$H$3 -> -5.5480048 | E9: =ABS(D9-C9) -> 0.54800477 | F9: =ABS(E9/C9) -> 0.10960095
A10: 34 | B10: =LN(A10) -> 3.5263605 | C10: -10 | D10: =B10*$H$2+$H$3 -> -5.5049363 | E10: =ABS(D10-C10) -> 4.4950637 | F10: =ABS(E10/C10) -> 0.44950637
A11: 34 | B11: =LN(A11) -> 3.5263605 | C11: -4 | D11: =B11*$H$2+$H$3 -> -5.5049363 | E11: =ABS(D11-C11) -> 1.5049363 | F11: =ABS(E11/C11) -> 0.37623407
A12: 41 | B12: =LN(A12) -> 3.7135721 | C12: -9 | D12: =B12*$H$2+$H$3 -> -5.5774278 | E12: =ABS(D12-C12) -> 3.4225722 | F12: =ABS(E12/C12) -> 0.38028579
A13: 37 | B13: =LN(A13) -> 3.6109179 | C13: -5 | D13: =B13*$H$2+$H$3 -> -5.5376784 | E13: =ABS(D13-C13) -> 0.53767836 | F13: =ABS(E13/C13) -> 0.10753567
A14: 39 | B14: =LN(A14) -> 3.6635616 | C14: -7 | D14: =B14*$H$2+$H$3 -> -5.5580629 | E14: =ABS(D14-C14) -> 1.4419371 | F14: =ABS(E14/C14) -> 0.20599101
A15: 36 | B15: =LN(A15) -> 3.5835189 | C15: -3 | D15: =B15*$H$2+$H$3 -> -5.527069 | E15: =ABS(D15-C15) -> 2.527069 | F15: =ABS(E15/C15) -> 0.84235633
A16: 34 | B16: =LN(A16) -> 3.5263605 | C16: -10 | D16: =B16*$H$2+$H$3 -> -5.5049363 | E16: =ABS(D16-C16) -> 4.4950637 | F16: =ABS(E16/C16) -> 0.44950637
... A25: 49 | B25: =LN(A25) -> 3.8918203 | C25: -9 | D25: =B25*$H$2+$H$3 -> -5.6464487 | E25: =ABS(D25-C25) -> 3.3535513 | F25: =ABS(E25/C25) -> 0.37261681
A26: 22 | B26: =LN(A26) -> 3.0910425 | C26: -6 | D26: =B26*$H$2+$H$3 -> -5.3363735 | E26: =ABS(D26-C26) -> 0.66362652 | F26: =ABS(E26/C26) -> 0.11060442 | G26: Коэффициент корреляции rxz | H26: =_xlfn.COVARIANCE.S(Таблица5[ln(X)], Таблица5[Z])/SQRT(_xlfn.VAR.S(Таблица5[ln(X)])*_xlfn.VAR.S(Таблица5[Z])) -> -0.033714379
A27: 48 | B27: =LN(A27) -> 3.871201 | C27: -2 | D27: =B27*$H$2+$H$3 -> -5.6384645 | E27: =ABS(D27-C27) -> 3.6384645 | F27: =ABS(E27/C27) -> 1.8192323 | G27: Коэффициент детерминации R² | H27: =1-SUMSQ(Таблица5[Остатки])/DEVSQ(Таблица5[Z]) -> 0.0011366594
A28: 30 | B28: =LN(A28) -> 3.4011974 | C28: -2 | D28: =B28*$H$2+$H$3 -> -5.4564709 | E28: =ABS(D28-C28) -> 3.4564709 | F28: =ABS(E28/C28) -> 1.7282354 | G28: Коэффициенты низкие, малая корреляционная зависимость
A29: 29 | B29: =LN(A29) -> 3.3672958 | C29: -8 | D29: =B29*$H$2+$H$3 -> -5.4433436 | E29: =ABS(D29-C29) -> 2.5566564 | F29: =ABS(E29/C29) -> 0.31958205
A30: 29 | B30: =LN(A30) -> 3.3672958 | C30: -9 | D30: =B30*$H$2+$H$3 -> -5.4433436 | E30: =ABS(D30-C30) -> 3.5566564 | F30: =ABS(E30/C30) -> 0.39518404 | G30: F-тест | H30: Значения
A31: 38 | B31: =LN(A31) -> 3.6375862 | C31: -2 | D31: =B31*$H$2+$H$3 -> -5.5480048 | E31: =ABS(D31-C31) -> 3.5480048 | F31: =ABS(E31/C31) -> 1.7740024 | G31: F-статистика | H31: =help_logarithmic_xz!E12 -> 0.10013985
A32: 37 | B32: =LN(A32) -> 3.6109179 | C32: -8 | D32: =B32*$H$2+$H$3 -> -5.5376784 | E32: =ABS(D32-C32) -> 2.4623216 | F32: =ABS(E32/C32) -> 0.3077902 | G32: F-критическое | H32: =FINV(0.05,help_logarithmic_xz!B12,help_logarithmic_xz!B13) -> 3.949321
A33: 55 | B33: =LN(A33) -> 4.0073332 | C33: -9 | D33: =B33*$H$2+$H$3 -> -5.6911773 | E33: =ABS(D33-C33) -> 3.3088227 | F33: =ABS(E33/C33) -> 0.36764697 | G33: Отвергаем гипотезу об описании данных гиперболической зависимостью (alpha = 0.05)
A34: 38 | B34: =LN(A34) -> 3.6375862 | C34: -7 | D34: =B34*$H$2+$H$3 -> -5.5480048 | E34: =ABS(D34-C34) -> 1.4519952 | F34: =ABS(E34/C34) -> 0.20742789
A35: 27 | B35: =LN(A35) -> 3.2958369 | C35: -2 | D35: =B35*$H$2+$H$3 -> -5.4156735 | E35: =ABS(D35-C35) -> 3.4156735 | F35: =ABS(E35/C35) -> 1.7078367 | G35: t-тест (на качество коэффициента a) | H35: Значения
A36: 44 | B36: =LN(A36) -> 3.7841896 | C36: -5 | D36: =B36*$H$2+$H$3 -> -5.6047722 | E36: =ABS(D36-C36) -> 0.60477221 | F36: =ABS(E36/C36) -> 0.12095444 | G36: t-статистика | H36: =help_logarithmic_xz!D18 -> -0.31644881
A37: 48 | B37: =LN(A37) -> 3.871201 | C37: -3 | D37: =B37*$H$2+$H$3 -> -5.6384645 | E37: =ABS(D37-C37) -> 2.6384645 | F37: =ABS(E37/C37) -> 0.87948818 | G37: t-критическое | H37: {=_xlfn.T.INV(0.95,COUNT(Таблица2[1/X]-2))} -> 1.6619611
A38: 35 | B38: =LN(A38) -> 3.5553481 | C38: -6 | D38: =B38*$H$2+$H$3 -> -5.5161607 | E38: =ABS(D38-C38) -> 0.48383926 | F38: =ABS(E38/C38) -> 0.080639876 | G38: Принимаем гипотезу о равенстве a = 0 (alpha = 0.05)
A39: 35 | B39: =LN(A39) -> 3.5553481 | C39: -10 | D39: =B39*$H$2+$H$3 -> -5.5161607 | E39: =ABS(D39-C39) -> 4.4838393 | F39: =ABS(E39/C39) -> 0.44838393
A40: 28 | B40: =LN(A40) -> 3.3322045 | C40: -4 | D40: =B40*$H$2+$H$3 -> -5.4297557 | E40: =ABS(D40-C40) -> 1.4297557 | F40: =ABS(E40/C40) -> 0.35743891 | G40: Все модели плохо аппроксимируют зависимость между X и Z, наименьшую среднюю ошибку показала линейная модель, наибольшую t- и F-статистики - гиперболическая (при этом линейная показала лучшие результаты в сравнении с логарифмической
A41: 39 | B41: =LN(A41) -> 3.6635616 | C41: -7 | D41: =B41*$H$2+$H$3 -> -5.5580629 | E41: =ABS(D41-C41) -> 1.4419371 | F41: =ABS(E41/C41) -> 0.20599101
A42: 38 | B42: =LN(A42) -> 3.6375862 | C42: -2 | D42: =B42*$H$2+$H$3 -> -5.5480048 | E42: =ABS(D42-C42) -> 3.5480048 | F42: =ABS(E42/C42) -> 1.7740024
A43: 35 | B43: =LN(A43) -> 3.5553481 | C43: -4 | D43: =B43*$H$2+$H$3 -> -5.5161607 | E43: =ABS(D43-C43) -> 1.5161607 | F43: =ABS(E43/C43) -> 0.37904019
A44: 40 | B44: =LN(A44) -> 3.6888795 | C44: -10 | D44: =B44*$H$2+$H$3 -> -5.5678664 | E44: =ABS(D44-C44) -> 4.4321336 | F44: =ABS(E44/C44) -> 0.44321336
A45: 44 | B45: =LN(A45) -> 3.7841896 | C45: -10 | D45: =B45*$H$2+$H$3 -> -5.6047722 | E45: =ABS(D45-C45) -> 4.3952278 | F45: =ABS(E45/C45) -> 0.43952278
A46: 30 | B46: =LN(A46) -> 3.4011974 | C46: -9 | D46: =B46*$H$2+$H$3 -> -5.4564709 | E46: =ABS(D46-C46) -> 3.5435291 | F46: =ABS(E46/C46) -> 0.39372546
A47: 43 | B47: =LN(A47) -> 3.7612001 | C47: -10 | D47: =B47*$H$2+$H$3 -> -5.5958703 | E47: =ABS(D47-C47) -> 4.4041297 | F47: =ABS(E47/C47) -> 0.44041297
A48: 43 | B48: =LN(A48) -> 3.7612001 | C48: -10 | D48: =B48*$H$2+$H$3 -> -5.5958703 | E48: =ABS(D48-C48) -> 4.4041297 | F48: =ABS(E48/C48) -> 0.44041297
...

Sheet help_logarithmic_xz
A1: ВЫВОД ИТОГОВ
A3: Регрессионная статистика
A4: Множественный R | B4: 0.033714379
A5: R-квадрат | B5: 0.0011366594
A6: Нормированный R-квадрат | B6: -0.01021406
A7: Стандартная ошибка | B7: 3.1033787
A8: Наблюдения | B8: 90
A10: Дисперсионный анализ
B11: df | C11: SS | D11: MS | E11: F | F11: Значимость F
A12: Регрессия | B12: 1 | C12: 0.96444284 | D12: 0.96444284 | E12: 0.10013985 | F12: 0.7524113
A13: Остаток | B13: 88 | C13: 847.52445 | D13: 9.6309596
A14: Итого | B14: 89 | C14: 848.48889
B16: Коэффициенты | C16: Стандартная ошибка | D16: t-статистика | E16: P-Значение | F16: Нижние 95% | G16: Верхние 95% | H16: Нижние 95.0% | I16: Верхние 95.0%
A17: Y-пересечение | B17: -4.1394677 | C17: 4.346814 | D17: -0.95229924 | E17: 0.34355363 | F17: -12.777847 | G17: 4.4989118 | H17: -12.777847 | I17: 4.4989118
A18: ln(X) | B18: -0.38721751 | C18: 1.223634 | D18: -0.31644881 | E18: 0.7524113 | F18: -2.8189329 | G18: 2.0444979 | H18: -2.8189329 | I18: 2.0444979
A22: ВЫВОД ОСТАТКА
A24: Наблюдение | B24: Предсказанное Z | C24: Остатки | D24: Стандартные остатки
A25: 1 | B25: -5.3858728 | C25: -1.6141272 | D25: -0.52306618
A26: 2 | B26: -5.6303123 | C26: -0.36968771 | D26: -0.1197992
A27: 3 | B27: -5.5867588 | C27: -4.4132412 | D27: -1.4301334
A28: 4 | B28: -5.5480048 | C28: 4.5480048 | D28: 1.4738042
A29: 5 | B29: -5.4564709 | C29: 3.4564709 | D29: 1.1200871
A30: 6 | B30: -5.4564709 | C30: -0.5435291 | D30: -0.17613339
A31: 7 | B31: -5.4814613 | C31: -0.51853866 | D31: -0.16803511
A32: 8 | B32: -5.5480048 | C32: 0.54800477 | D32: 0.17758375
A33: 9 | B33: -5.5049363 | C33: -4.4950637 | D33: -1.4566484
A34: 10 | B34: -5.5049363 | C34: 1.5049363 | D34: 0.4876823
A35: 11 | B35: -5.5774278 | C35: -3.4225722 | D35: -1.109102
A36: 12 | B36: -5.5376784 | C36: 0.53767836 | D36: 0.17423743
... A114: 90 | B114: -5.5161607 | C114: -4.4838393 | D114: -1.4530111

Sheet linear_yz
A1: Y | B1: Z | C1: Предсказанные значения | D1: Остатки | E1: Нормированные остатки | F1: Шаг остатка | G1: Коэффициенты | H1: Значения | I1: Выводы
A2: 233 | B2: -7 | C2: =$H$3+$H$2*A2 -> -5.5097892 | D2: =ABS(Таблица7[[#This Row],[Предсказанные значения]]-Таблица7[[#This Row],[Z]]) -> 1.4902108 | E2: =ABS(Таблица7[[#This Row],[Остатки]]/Таблица7[[#This Row],[Z]]) -> 0.21288726 | F2: =Таблица7[[#This Row],[Нормированные остатки]]-E3 -> 0.1316546 | G2: a | H2: -1.4144866e-05 | I2: В начальный момент предсказанное значение Z было равно а
A3: 432 | B3: -6 | C3: =$H$3+$H$2*A3 -> -5.512604 | D3: =ABS(Таблица7[[#This Row],[Предсказанные значения]]-Таблица7[[#This Row],[Z]]) -> 0.48739598 | E3: =ABS(Таблица7[[#This Row],[Остатки]]/Таблица7[[#This Row],[Z]]) -> 0.081232663 | F3: =Таблица7[[#This Row],[Нормированные остатки]]-E4 -> -0.36757342 | G3: b | H3: -5.5064934 | I3: При изменении y на одну единицу Z в среднем изменяется на b
A4: 385 | B4: -10 | C4: =$H$3+$H$2*A4 -> -5.5119392 | D4: =ABS(Таблица7[[#This Row],[Предсказанные значения]]-Таблица7[[#This Row],[Z]]) -> 4.4880608 | E4: =ABS(Таблица7[[#This Row],[Остатки]]/Таблица7[[#This Row],[Z]]) -> 0.44880608 | F4: =Таблица7[[#This Row],[Нормированные остатки]]-E5 -> -4.0625956
A5: 347 | B5: -1 | C5: =$H$3+$H$2*A5 -> -5.5114017 | D5: =ABS(Таблица7[[#This Row],[Предсказанные значения]]-Таблица7[[#This Row],[Z]]) -> 4.5114017 | E5: =ABS(Таблица7[[#This Row],[Остатки]]/Таблица7[[#This Row],[Z]]) -> 4.5114017 | F5: =Таблица7[[#This Row],[Нормированные остатки]]-E6 -> 2.7562171
A6: 274 | B6: -2 | C6: =$H$3+$H$2*A6 -> -5.5103691 | D6: =ABS(Таблица7[[#This Row],[Предсказанные значения]]-Таблица7[[#This Row],[Z]]) -> 3.5103691 | E6: =ABS(Таблица7[[#This Row],[Остатки]]/Таблица7[[#This Row],[Z]]) -> 1.7551846 | F6: =Таблица7[[#This Row],[Нормированные остатки]]-E7 -> 1.6735841
A7: 276 | B7: -6 | C7: =$H$3+$H$2*A7 -> -5.5103974 | D7: =ABS(Таблица7[[#This Row],[Предсказанные значения]]-Таблица7[[#This Row],[Z]]) -> 0.48960258 | E7: =ABS(Таблица7[[#This Row],[Остатки]]/Таблица7[[#This Row],[Z]]) -> 0.081600429 | F7: =Таблица7[[#This Row],[Нормированные остатки]]-E8 -> 4.2434598e-05
A8: 294 | B8: -6 | C8: =$H$3+$H$2*A8 -> -5.510652 | D8: =ABS(Таблица7[[#This Row],[Предсказанные значения]]-Таблица7[[#This Row],[Z]]) -> 0.48934797 | E8: =ABS(Таблица7[[#This Row],[Остатки]]/Таблица7[[#This Row],[Z]]) -> 0.081557995 | F8: =Таблица7[[#This Row],[Нормированные остатки]]-E9 -> -0.020725176
A9: 348 | B9: -5 | C9: =$H$3+$H$2*A9 -> -5.5114159 | D9: =ABS(Таблица7[[#This Row],[Предсказанные значения]]-Таблица7[[#This Row],[Z]]) -> 0.51141585 | E9: =ABS(Таблица7[[#This Row],[Остатки]]/Таблица7[[#This Row],[Z]]) -> 0.10228317 | F9: =Таблица7[[#This Row],[Нормированные остатки]]-E10 -> -0.34662192
A10: 315 | B10: -10 | C10: =$H$3+$H$2*A10 -> -5.5109491 | D10: =ABS(Таблица7[[#This Row],[Предсказанные значения]]-Таблица7[[#This Row],[Z]]) -> 4.4890509 | E10: =ABS(Таблица7[[#This Row],[Остатки]]/Таблица7[[#This Row],[Z]]) -> 0.44890509 | F10: =Таблица7[[#This Row],[Нормированные остатки]]-E11 -> 0.071196114
A11: 307 | B11: -4 | C11: =$H$3+$H$2*A11 -> -5.5108359 | D11: =ABS(Таблица7[[#This Row],[Предсказанные значения]]-Таблица7[[#This Row],[Z]]) -> 1.5108359 | E11: =ABS(Таблица7[[#This Row],[Остатки]]/Таблица7[[#This Row],[Z]]) -> 0.37770898 | F11: =Таблица7[[#This Row],[Нормированные остатки]]-E12 -> -0.009865904
A12: 377 | B12: -9 | C12: =$H$3+$H$2*A12 -> -5.5118261 | D12: =ABS(Таблица7[[#This Row],[Предсказанные значения]]-Таблица7[[#This Row],[Z]]) -> 3.4881739 | E12: =ABS(Таблица7[[#This Row],[Остатки]]/Таблица7[[#This Row],[Z]]) -> 0.38757488 | F12: =Таблица7[[#This Row],[Нормированные остатки]]-E13 -> 0.28532
A13: 338 | B13: -5 | C13: =$H$3+$H$2*A13 -> -5.5112744 | D13: =ABS(Таблица7[[#This Row],[Предсказанные значения]]-Таблица7[[#This Row],[Z]]) -> 0.51127441 | E13: =ABS(Таблица7[[#This Row],[Остатки]]/Таблица7[[#This Row],[Z]]) -> 0.10225488 | F13: =Таблица7[[#This Row],[Нормированные остатки]]-E14 -> -0.11038989
A14: 353 | B14: -7 | C14: =$H$3+$H$2*A14 -> -5.5114866 | D14: =ABS(Таблица7[[#This Row],[Предсказанные значения]]-Таблица7[[#This Row],[Z]]) -> 1.4885134 | E14: =ABS(Таблица7[[#This Row],[Остатки]]/Таблица7[[#This Row],[Z]]) -> 0.21264477 | F14: =Таблица7[[#This Row],[Нормированные остатки]]-E15 -> -0.6244184
A15: 332 | B15: -3 | C15: =$H$3+$H$2*A15 -> -5.5111895 | D15: =ABS(Таблица7[[#This Row],[Предсказанные значения]]-Таблица7[[#This Row],[Z]]) -> 2.5111895 | E15: =ABS(Таблица7[[#This Row],[Остатки]]/Таблица7[[#This Row],[Z]]) -> 0.83706318 | F15: =Таблица7[[#This Row],[Нормированные остатки]]-E16 -> 0.38814677
... A18: 285 | B18: -3 | C18: =$H$3+$H$2*A18 -> -5.5105247 | D18: =ABS(Таблица7[[#This Row],[Предсказанные значения]]-Таблица7[[#This Row],[Z]]) -> 2.5105247 | E18: =ABS(Таблица7[[#This Row],[Остатки]]/Таблица7[[#This Row],[Z]]) -> 0.83684158 | F18: =Таблица7[[#This Row],[Нормированные остатки]]-E19 -> 0.73447636
A19: 377 | B19: -5 | C19: =$H$3+$H$2*A19 -> -5.5118261 | D19: =ABS(Таблица7[[#This Row],[Предсказанные значения]]-Таблица7[[#This Row],[Z]]) -> 0.51182606 | E19: =ABS(Таблица7[[#This Row],[Остатки]]/Таблица7[[#This Row],[Z]]) -> 0.10236521 | F19: =Таблица7[[#This Row],[Нормированные остатки]]-E20 -> 0.00067895357 | N19: Вообще, можем сразу предположить плохой результат аппроксимации по Y на основе выводов из аппроксимации по X, так как между ними наблюдается чёткая линейная зависимость
A20: 137 | B20: -5 | C20: =$H$3+$H$2*A20 -> -5.5084313 | D20: =ABS(Таблица7[[#This Row],[Предсказанные значения]]-Таблица7[[#This Row],[Z]]) -> 0.50843129 | E20: =ABS(Таблица7[[#This Row],[Остатки]]/Таблица7[[#This Row],[Z]]) -> 0.10168626 | F20: =Таблица7[[#This Row],[Нормированные остатки]]-E21 -> -4.4082727
A21: 245 | B21: -1 | C21: =$H$3+$H$2*A21 -> -5.5099589 | D21: =ABS(Таблица7[[#This Row],[Предсказанные значения]]-Таблица7[[#This Row],[Z]]) -> 4.5099589 | E21: =ABS(Таблица7[[#This Row],[Остатки]]/Таблица7[[#This Row],[Z]]) -> 4.5099589 | F21: =Таблица7[[#This Row],[Нормированные остатки]]-E22 -> -2.0024895
A22: 421 | B22: 1 | C22: =$H$3+$H$2*A22 -> -5.5124484 | D22: =ABS(Таблица7[[#This Row],[Предсказанные значения]]-Таблица7[[#This Row],[Z]]) -> 6.5124484 | E22: =ABS(Таблица7[[#This Row],[Остатки]]/Таблица7[[#This Row],[Z]]) -> 6.5124484 | F22: =Таблица7[[#This Row],[Нормированные остатки]]-E23 -> 6.0635405
A23: 313 | B23: -10 | C23: =$H$3+$H$2*A23 -> -5.5109208 | D23: =ABS(Таблица7[[#This Row],[Предсказанные значения]]-Таблица7[[#This Row],[Z]]) -> 4.4890792 | E23: =ABS(Таблица7[[#This Row],[Остатки]]/Таблица7[[#This Row],[Z]]) -> 0.44890792 | F23: =Таблица7[[#This Row],[Нормированные остатки]]-E24 -> -0.38828256
A24: 359 | B24: -3 | C24: =$H$3+$H$2*A24 -> -5.5115714 | D24: =ABS(Таблица7[[#This Row],[Предсказанные значения]]-Таблица7[[#This Row],[Z]]) -> 2.5115714 | E24: =ABS(Таблица7[[#This Row],[Остатки]]/Таблица7[[#This Row],[Z]]) -> 0.83719048 | F24: =Таблица7[[#This Row],[Нормированные остатки]]-E25 -> 0.44971933
A25: 443 | B25: -9 | C25: =$H$3+$H$2*A25 -> -5.5127596 | D25: =ABS(Таблица7[[#This Row],[Предсказанные значения]]-Таблица7[[#This Row],[Z]]) -> 3.4872404 | E25: =ABS(Таблица7[[#This Row],[Остатки]]/Таблица7[[#This Row],[Z]]) -> 0.38747115 | F25: =Таблица7[[#This Row],[Нормированные остатки]]-E26 -> 0.30569391
A26: 201 | B26: -6 | C26: =$H$3+$H$2*A26 -> -5.5093366 | D26: =ABS(Таблица7[[#This Row],[Предсказанные значения]]-Таблица7[[#This Row],[Z]]) -> 0.49066344 | E26: =ABS(Таблица7[[#This Row],[Остатки]]/Таблица7[[#This Row],[Z]]) -> 0.08177724 | F26: =Таблица7[[#This Row],[Нормированные остатки]]-E27 -> -1.6745814 | G26: Средняя ошибка аппроксимации | H26: =SUM(Таблица7[Нормированные остатки])/COUNT(Таблица7[Y]) -> 0.92657972
A27: 440 | B27: -2 | C27: =$H$3+$H$2*A27 -> -5.5127172 | D27: =ABS(Таблица7[[#This Row],[Предсказанные значения]]-Таблица7[[#This Row],[Z]]) -> 3.5127172 | E27: =ABS(Таблица7[[#This Row],[Остатки]]/Таблица7[[#This Row],[Z]]) -> 1.7563586 | F27: =Таблица7[[#This Row],[Нормированные остатки]]-E28 -> 0.0011740239 | G27: Средняя эластичность | H27: =H2*AVERAGE(Таблица7[Y])/AVERAGE(Таблица7[Z]) -> 0.00083788368
A28: 274 | B28: -2 | C28: =$H$3+$H$2*A28 -> -5.5103691 | D28: =ABS(Таблица7[[#This Row],[Предсказанные значения]]-Таблица7[[#This Row],[Z]]) -> 3.5103691 | E28: =ABS(Таблица7[[#This Row],[Остатки]]/Таблица7[[#This Row],[Z]]) -> 1.7551846 | F28: =Таблица7[[#This Row],[Нормированные остатки]]-E29 -> 1.4439577
A29: 261 | B29: -8 | C29: =$H$3+$H$2*A29 -> -5.5101853 | D29: =ABS(Таблица7[[#This Row],[Предсказанные значения]]-Таблица7[[#This Row],[Z]]) -> 2.4898147 | E29: =ABS(Таблица7[[#This Row],[Остатки]]/Таблица7[[#This Row],[Z]]) -> 0.31122684 | F29: =Таблица7[[#This Row],[Нормированные остатки]]-E30 -> -0.076516206 | G29: Проверка условий Гаусса-Маркова | H29: Выводы, значения
A30: 270 | B30: -9 | C30: =$H$3+$H$2*A30 -> -5.5103126 | D30: =ABS(Таблица7[[#This Row],[Предсказанные значения]]-Таблица7[[#This Row],[Z]]) -> 3.4896874 | E30: =ABS(Таблица7[[#This Row],[Остатки]]/Таблица7[[#This Row],[Z]]) -> 0.38774305 | F30: =Таблица7[[#This Row],[Нормированные остатки]]-E31 -> -1.3679437 | G30: МE = 0 | H30: =AVERAGE(Таблица7[Остатки])/COUNT(Таблица7[Y]) -> 0.028641544
A31: 345 | B31: -2 | C31: =$H$3+$H$2*A31 -> -5.5113734 | D31: =ABS(Таблица7[[#This Row],[Предсказанные значения]]-Таблица7[[#This Row],[Z]]) -> 3.5113734 | E31: =ABS(Таблица7[[#This Row],[Остатки]]/Таблица7[[#This Row],[Z]]) -> 1.7556867 | F31: =Таблица7[[#This Row],[Нормированные остатки]]-E32 -> 1.4445889 | G31: Dei = const | H31: Визуально на графике остатков точки случайно распределены вокруг 0
A32: 334 | B32: -8 | C32: =$H$3+$H$2*A32 -> -5.5112178 | D32: =ABS(Таблица7[[#This Row],[Предсказанные значения]]-Таблица7[[#This Row],[Z]]) -> 2.4887822 | E32: =ABS(Таблица7[[#This Row],[Остатки]]/Таблица7[[#This Row],[Z]]) -> 0.31109777 | F32: =Таблица7[[#This Row],[Нормированные остатки]]-E33 -> -0.076286941 | G32: Отсутствие автокорреляции (cov(ei,ej) = 0) | H32: =SUMSQ(Таблица7[Шаг остатка])/SUMSQ(Таблица7[Нормированные остатки]) -> 1.1896646 | I32: Должно быть близко к 2, чтобы автокорреляция отсутствовала
A33: 498 | B33: -9 | C33: =$H$3+$H$2*A33 -> -5.5135376 | D33: =ABS(Таблица7[[#This Row],[Предсказанные значения]]-Таблица7[[#This Row],[Z]]) -> 3.4864624 | E33: =ABS(Таблица7[[#This Row],[Остатки]]/Таблица7[[#This Row],[Z]]) -> 0.38738471 | F33: =Таблица7[[#This Row],[Нормированные остатки]]-E34 -> 0.17471771 | G33: Не выполнены 1 и 3 условия!
A34: 342 | B34: -7 | C34: =$H$3+$H$2*A34 -> -5.511331 | D34: =ABS(Таблица7[[#This Row],[Предсказанные значения]]-Таблица7[[#This Row],[Z]]) -> 1.488669 | E34: =ABS(Таблица7[[#This Row],[Остатки]]/Таблица7[[#This Row],[Z]]) -> 0.212667 | F34: =Таблица7[[#This Row],[Нормированные остатки]]-E35 -> -1.5423478 | G34: К тому же модель явно имеет не линейную зависимость
A35: 250 | B35: -2 | C35: =$H$3+$H$2*A35 -> -5.5100297 | D35: =ABS(Таблица7[[#This Row],[Предсказанные значения]]-Таблица7[[#This Row],[Z]]) -> 3.5100297 | E35: =ABS(Таблица7[[#This Row],[Остатки]]/Таблица7[[#This Row],[Z]]) -> 1.7550148 | F35: =Таблица7[[#This Row],[Нормированные остатки]]-E36 -> 1.6525761
A36: 403 | B36: -5 | C36: =$H$3+$H$2*A36 -> -5.5121938 | D36: =ABS(Таблица7[[#This Row],[Предсказанные значения]]-Таблица7[[#This Row],[Z]]) -> 0.51219382 | E36: =ABS(Таблица7[[#This Row],[Остатки]]/Таблица7[[#This Row],[Z]]) -> 0.10243876 | F36: =Таблица7[[#This Row],[Нормированные остатки]]-E37 -> -0.73510534 | G36: Коэффициент корреляции rxz | H36: =_xlfn.COVARIANCE.S(Yval, Таблица7[Z])/SQRT(_xlfn.VAR.S(Yval)*_xlfn.VAR.S(Таблица7[Z])) -> -0.00036620508
A37: 434 | B37: -3 | C37: =$H$3+$H$2*A37 -> -5.5126323 | D37: =ABS(Таблица7[[#This Row],[Предсказанные значения]]-Таблица7[[#This Row],[Z]]) -> 2.5126323 | E37: =ABS(Таблица7[[#This Row],[Остатки]]/Таблица7[[#This Row],[Z]]) -> 0.8375441 | F37: =Таблица7[[#This Row],[Нормированные остатки]]-E38 -> 0.7560474 | G37: Коэффициент детерминации R² | H37: =1-SUMSQ(Таблица7[Остатки])/DEVSQ(Таблица7[Z]) -> 1.3410616e-07
A38: 320 | B38: -6 | C38: =$H$3+$H$2*A38 -> -5.5110198 | D38: =ABS(Таблица7[[#This Row],[Предсказанные значения]]-Таблица7[[#This Row],[Z]]) -> 0.4889802 | E38: =ABS(Таблица7[[#This Row],[Остатки]]/Таблица7[[#This Row],[Z]]) -> 0.0814967 | F38: =Таблица7[[#This Row],[Нормированные остатки]]-E39 -> -0.36740415 | G38: Имеем малую связь между Y и Z, данные плохо линеаризуемы, так как R явно не близок к 1
A39: 318 | B39: -10 | C39: =$H$3+$H$2*A39 -> -5.5109915 | D39: =ABS(Таблица7[[#This Row],[Предсказанные значения]]-Таблица7[[#This Row],[Z]]) -> 4.4890085 | E39: =ABS(Таблица7[[#This Row],[Остатки]]/Таблица7[[#This Row],[Z]]) -> 0.44890085 | F39: =Таблица7[[#This Row],[Нормированные остатки]]-E40 -> 0.071372217
A40: 256 | B40: -4 | C40: =$H$3+$H$2*A40 -> -5.5101145 | D40: =ABS(Таблица7[[#This Row],[Предсказанные значения]]-Таблица7[[#This Row],[Z]]) -> 1.5101145 | E40: =ABS(Таблица7[[#This Row],[Остатки]]/Таблица7[[#This Row],[Z]]) -> 0.37752863 | F40: =Таблица7[[#This Row],[Нормированные остатки]]-E41 -> 0.16489396 | G40: F-тест | H40: Значения
A41: 358 | B41: -7 | C41: =$H$3+$H$2*A41 -> -5.5115573 | D41: =ABS(Таблица7[[#This Row],[Предсказанные значения]]-Таблица7[[#This Row],[Z]]) -> 1.4884427 | E41: =ABS(Таблица7[[#This Row],[Остатки]]/Таблица7[[#This Row],[Z]]) -> 0.21263467 | F41: =Таблица7[[#This Row],[Нормированные остатки]]-E42 -> -1.5430662 | G41: F-статистика | H41: =help_linear_yz!E12 -> 1.1801344e-05
A42: 347 | B42: -2 | C42: =$H$3+$H$2*A42 -> -5.5114017 | D42: =ABS(Таблица7[[#This Row],[Предсказанные значения]]-Таблица7[[#This Row],[Z]]) -> 3.5114017 | E42: =ABS(Таблица7[[#This Row],[Остатки]]/Таблица7[[#This Row],[Z]]) -> 1.7557009 | F42: =Таблица7[[#This Row],[Нормированные остатки]]-E43 -> 1.377953 | G42: F-критическое | H42: =FINV(0.05,help_linear_yz!B12,help_linear_yz!B13) -> 3.949321
...

Sheet help_linear_yz
A1: ВЫВОД ИТОГОВ
A3: Регрессионная статистика
A4: Множественный R | B4: 0.00036620508
A5: R-квадрат | B5: 1.3410616e-07
A6: Нормированный R-квадрат | B6: -0.011363501
A7: Стандартная ошибка | B7: 3.1051438
A8: Наблюдения | B8: 90
A10: Дисперсионный анализ
B11: df | C11: SS | D11: MS | E11: F | F11: Значимость F
A12: Регрессия | B12: 1 | C12: 0.00011378759 | D12: 0.00011378759 | E12: 1.1801344e-05 | F12: 0.9972668
A13: Остаток | B13: 88 | C13: 848.48878 | D13: 9.6419179
A14: Итого | B14: 89 | C14: 848.48889
B16: Коэффициенты | C16: Стандартная ошибка | D16: t-статистика | E16: P-Значение | F16: Нижние 95% | G16: Верхние 95% | H16: Нижние 95.0% | I16: Верхние 95.0%
A17: Y-пересечение | B17: -5.5064934 | C17: 1.3834559 | D17: -3.9802451 | E17: 0.00014121466 | F17: -8.2558213 | G17: -2.7571656 | H17: -8.2558213 | I17: -2.7571656
A18: Y | B18: -1.4144866e-05 | C18: 0.0041174952 | D18: -0.0034353084 | E18: 0.9972668 | F18: -0.0081968014 | G18: 0.0081685117 | H18: -0.0081968014 | I18: 0.0081685117
A22: ВЫВОД ОСТАТКА
A24: Наблюдение | B24: Предсказанное Z | C24: Остатки | D24: Стандартные остатки
A25: 1 | B25: -5.5097892 | C25: -1.4902108 | D25: -0.48263594
A26: 2 | B26: -5.512604 | C26: -0.48739598 | D26: -0.15785338
A27: 3 | B27: -5.5119392 | C27: -4.4880608 | D27: -1.4535524
A28: 4 | B28: -5.5114017 | C28: 4.5114017 | D28: 1.4611118
A29: 5 | B29: -5.5103691 | C29: 3.5103691 | D29: 1.1369065
A30: 6 | B30: -5.5103974 | C30: -0.48960258 | D30: -0.15856804
A31: 7 | B31: -5.510652 | C31: -0.48934797 | D31: -0.15848558
A32: 8 | B32: -5.5114159 | C32: 0.51141585 | D32: 0.16563272
A33: 9 | B33: -5.5109491 | C33: -4.4890509 | D33: -1.453873
A34: 10 | B34: -5.5108359 | C34: 1.5108359 | D34: 0.48931582
A35: 11 | B35: -5.5118261 | C35: -3.4881739 | D35: -1.1297181
A36: 12 | B36: -5.5112744 | C36: 0.51127441 | D36: 0.16558691
... A114: 90 | B114: -5.5110764 | C114: -4.4889236 | D114: -1.4538318

Sheet exponential_yz
A1: Y | B1: exp(-0.01Y) | C1: Z | D1: Предсказанные значения | E1: Остатки | F1: Нормированные остатки | G1: Коэффициенты | H1: Значения
A2: 233 | B2: =EXP(-0.01*A2) -> 0.097295747 | C2: -7 | D2: =$H$2*Таблица245[[#This Row],[exp(-0.01Y)]]+$H$3 -> -5.2389222 | E2: =ABS(Таблица245[[#This Row],[Предсказанные значения]]-Таблица245[[#This Row],[Z]]) -> 1.7610778 | F2: =ABS(Таблица245[[#This Row],[Остатки]]/Таблица245[[#This Row],[Z]]) -> 0.25158255 | G2: a | H2: 6.0391731
A3: 432 | B3: =EXP(-0.01*A3) -> 0.013299884 | C3: -6 | D3: =$H$2*Таблица245[[#This Row],[exp(-0.01Y)]]+$H$3 -> -5.7461877 | E3: =ABS(Таблица245[[#This Row],[Предсказанные значения]]-Таблица245[[#This Row],[Z]]) -> 0.25381228 | F3: =ABS(Таблица245[[#This Row],[Остатки]]/Таблица245[[#This Row],[Z]]) -> 0.042302046 | G3: b | H3: -5.826508
A4: 385 | B4: =EXP(-0.01*A4) -> 0.021279736 | C4: -10 | D4: =$H$2*Таблица245[[#This Row],[exp(-0.01Y)]]+$H$3 -> -5.697996 | E4: =ABS(Таблица245[[#This Row],[Предсказанные значения]]-Таблица245[[#This Row],[Z]]) -> 4.302004 | F4: =ABS(Таблица245[[#This Row],[Остатки]]/Таблица245[[#This Row],[Z]]) -> 0.4302004 | G4: Средняя ошибка аппроксимации | H4: =SUM(Таблица245[Нормированные остатки])/COUNT(Таблица245[Y]) -> 0.92686504
A5: 347 | B5: =EXP(-0.01*A5) -> 0.031117031 | C5: -1 | D5: =$H$2*Таблица245[[#This Row],[exp(-0.01Y)]]+$H$3 -> -5.6385869 | E5: =ABS(Таблица245[[#This Row],[Предсказанные значения]]-Таблица245[[#This Row],[Z]]) -> 4.6385869 | F5: =ABS(Таблица245[[#This Row],[Остатки]]/Таблица245[[#This Row],[Z]]) -> 4.6385869
A6: 274 | B6: =EXP(-0.01*A6) -> 0.064570347 | C6: -2 | D6: =$H$2*Таблица245[[#This Row],[exp(-0.01Y)]]+$H$3 -> -5.4365565 | E6: =ABS(Таблица245[[#This Row],[Предсказанные значения]]-Таблица245[[#This Row],[Z]]) -> 3.4365565 | F6: =ABS(Таблица245[[#This Row],[Остатки]]/Таблица245[[#This Row],[Z]]) -> 1.7182783
A7: 276 | B7: =EXP(-0.01*A7) -> 0.063291768 | C7: -6 | D7: =$H$2*Таблица245[[#This Row],[exp(-0.01Y)]]+$H$3 -> -5.4442781 | E7: =ABS(Таблица245[[#This Row],[Предсказанные значения]]-Таблица245[[#This Row],[Z]]) -> 0.55572193 | F7: =ABS(Таблица245[[#This Row],[Остатки]]/Таблица245[[#This Row],[Z]]) -> 0.092620321
A8: 294 | B8: =EXP(-0.01*A8) -> 0.052865729 | C8: -6 | D8: =$H$2*Таблица245[[#This Row],[exp(-0.01Y)]]+$H$3 -> -5.5072427 | E8: =ABS(Таблица245[[#This Row],[Предсказанные значения]]-Таблица245[[#This Row],[Z]]) -> 0.49275727 | F8: =ABS(Таблица245[[#This Row],[Остатки]]/Таблица245[[#This Row],[Z]]) -> 0.082126211
A9: 348 | B9: =EXP(-0.01*A9) -> 0.030807411 | C9: -5 | D9: =$H$2*Таблица245[[#This Row],[exp(-0.01Y)]]+$H$3 -> -5.6404567 | E9: =ABS(Таблица245[[#This Row],[Предсказанные значения]]-Таблица245[[#This Row],[Z]]) -> 0.64045673 | F9: =ABS(Таблица245[[#This Row],[Остатки]]/Таблица245[[#This Row],[Z]]) -> 0.12809135
A10: 315 | B10: =EXP(-0.01*A10) -> 0.042852127 | C10: -10 | D10: =$H$2*Таблица245[[#This Row],[exp(-0.01Y)]]+$H$3 -> -5.5677166 | E10: =ABS(Таблица245[[#This Row],[Предсказанные значения]]-Таблица245[[#This Row],[Z]]) -> 4.4322834 | F10: =ABS(Таблица245[[#This Row],[Остатки]]/Таблица245[[#This Row],[Z]]) -> 0.44322834
A11: 307 | B11: =EXP(-0.01*A11) -> 0.046421155 | C11: -4 | D11: =$H$2*Таблица245[[#This Row],[exp(-0.01Y)]]+$H$3 -> -5.5461626 | E11: =ABS(Таблица245[[#This Row],[Предсказанные значения]]-Таблица245[[#This Row],[Z]]) -> 1.5461626 | F11: =ABS(Таблица245[[#This Row],[Остатки]]/Таблица245[[#This Row],[Z]]) -> 0.38654066
A12: 377 | B12: =EXP(-0.01*A12) -> 0.023052063 | C12: -9 | D12: =$H$2*Таблица245[[#This Row],[exp(-0.01Y)]]+$H$3 -> -5.6872926 | E12: =ABS(Таблица245[[#This Row],[Предсказанные значения]]-Таблица245[[#This Row],[Z]]) -> 3.3127074 | F12: =ABS(Таблица245[[#This Row],[Остатки]]/Таблица245[[#This Row],[Z]]) -> 0.3680786
A13: 338 | B13: =EXP(-0.01*A13) -> 0.034047455 | C13: -5 | D13: =$H$2*Таблица245[[#This Row],[exp(-0.01Y)]]+$H$3 -> -5.6208895 | E13: =ABS(Таблица245[[#This Row],[Предсказанные значения]]-Таблица245[[#This Row],[Z]]) -> 0.62088955 | F13: =ABS(Таблица245[[#This Row],[Остатки]]/Таблица245[[#This Row],[Z]]) -> 0.12417791
